Workbook
Name ____DAT10: #REF!
Name ____DAT10: #REF!
Name ____DAT10: #REF!
Name ____DAT11: #REF!
Name ____DAT11: #REF!
Name ____DAT12: [1]Sheet1!#REF!
Name ____DAT12: [1]Sheet1!#REF!
Name ____DAT13: [1]Sheet1!#REF!
Name ____DAT13: [1]Sheet1!#REF!
Name ____DAT14: #REF!
Name ____DAT14: #REF!
Name ____DAT14: #REF!
Name ____DAT2: #REF!
Name ____DAT2: #REF!
Name ____DAT3: #REF!
Name ____DAT4: #REF!
Name ____DAT5: #REF!
Name ____DAT6: #REF!
Name ____DAT7: #REF!
Name ____DAT8: #REF!
Name ____DAT9: #REF!
Name ___DAT1: #REF!
Name ___DAT10: #REF!
Name ___DAT11: #REF!
Name ___DAT12: [1]Sheet1!#REF!
Name ___DAT13: [1]Sheet1!#REF!
Name ___DAT14: #REF!
Name ___DAT2: #REF!
Name ___DAT3: #REF!
Name ___DAT4: #REF!
Name ___DAT5: #REF!
Name ___DAT6: #REF!
Name ___DAT7: #REF!
Name ___DAT8: #REF!
Name ___DAT9: #REF!
Name __DAT1: #REF!
Name __DAT1: #REF!
Name __DAT10: #REF!
Name __DAT11: #REF!
Name __DAT12: [1]Sheet1!#REF!
Name __DAT13: [1]Sheet1!#REF!
Name __DAT14: #REF!
Name __DAT14: #REF!
Name __DAT2: #REF!
Name __DAT2: #REF!
Name __DAT3: #REF!
Name __DAT3: #REF!
Name __DAT4: #REF!
Name __DAT5: #REF!
Name __DAT6: #REF!
Name __DAT7: #REF!
Name __DAT8: #REF!
Name __DAT9: #REF!
Name __shared_11_0_0: NA()
Name __shared_11_0_1: NA()
Name __shared_11_0_2: NA()
Name __shared_11_0_3: NA()
Name __shared_13_0_0: NA()
Name __shared_13_0_1: NA()
Name __shared_13_0_10: NA()

Sheet NBD-MF-01-SOFP
A1: Statement of Financial Position a | D1: Rs.'000 | E1: Rs.
D2: 45900
C3: BS Out (Should be zero) | D3: 0 | E3: -0.63859558
A4: 1.1.0.0.0.0 | B4: BS-1.1.0.0.0.0 | C4: Assets b | D4: 67585381 | E4: 6.758538e+10
A5: 1.1.1.0.0.0 | B5: BS-1.1.1.0.0.0 | C5: Cash and Cash Equivalents c | D5: 726315 | E5: 7.2631542e+08
A6: 1.1.1.1.0.0 | B6: BS-1.1.1.1.0.0 | C6: Cash in Hand (LKR) | D6: 285966 | E6: 2.8596616e+08
A7: 1.1.1.2.0.0 | B7: BS-1.1.1.2.0.0 | C7: Cash in Hand (Foreign Currency) | D7: 0 | E7: 0
A8: 1.1.1.3.0.0 | B8: BS-1.1.1.3.0.0 | C8: Demand Deposits with banks (LKR) | D8: 418563 | E8: 4.1856302e+08
A9: 1.1.1.4.0.0 | B9: BS-1.1.1.4.0.0 | C9: Demand Deposits with banks (Foreign Currency) | D9: 21786 | E9: 21786244
A10: 1.1.1.5.0.0 | B10: BS-1.1.1.5.0.0 | C10: Gold Bullion in Hand | D10: 0 | E10: 0
A11: 1.1.2.0.0.0 | B11: BS-1.1.2.0.0.0 | C11: Balances with Central Bank and Financial Institutions c,d | D11: 1925180 | E11: 1.9251795e+09
A12: 1.1.2.1.0.0 | B12: BS-1.1.2.1.0.0 | C12: Balances with Central Bank | D12: 0 | E12: 0
A13: 1.1.2.2.0.0 | B13: BS-1.1.2.2.0.0 | C13: Balances with Banks and Other Financial Institutions (LKR) | D13: 1025521 | E13: 1025520548
A14: 1.1.2.3.0.0 | B14: BS-1.1.2.3.0.0 | C14: Balances with Banks and Other Financial Institutions (Foreign Currency) | D14: 899659 | E14: 8.9965894e+08
A15: 1.1.3.0.0.0 | B15: BS-1.1.3.0.0.0 | C15: Securities Purchased under Resale Agreements c | D15: 0 | E15: 0
... A137: 1.3.4.0.0.0 | B137: BS-1.3.4.0.0.0 | C137: Other | D137: 0 | E137: 0

Sheet NBD-MF-11-IS
A1: NBD-MF-11-IS:Interest Rate Sensitivity
A2: Monthly Financial Return (LKR '000)
A4: Code | B4: Assets or Liability 1(a) | C4: 0 to 1 Month (b) | D4: 0 to 3 Months (c) | E4: 0 to 6 Months (d) | F4: 0 to 12 Months (e)
A5: 11.1.0.0.0.0 | B5: Interest Bearing Assets | C5: =SUM(C6:C10) -> 4099575.5 | D5: =SUM(D6:D10) -> 6898606.5 | E5: =SUM(E6:E10) -> 11750148 | F5: =SUM(F6:F10) -> 26268515
A6: 11.1.1.0.0.0 | B6: Bank Balances and Placements | C6: =SUM(Investments!$P$68:Q68)+SUM(Investments!$P$78:Q78) -> 1025520.5 | D6: =SUM(Investments!$P$68:R68)+SUM(Investments!$P$78:R78) -> 1025520.5 | E6: =SUM(Investments!$P$68:S68)+SUM(Investments!$P$78:S78) -> 1025520.5 | F6: =SUM(Investments!$P$68:T68)+SUM(Investments!$P$78:T78) -> 1025520.5
A7: 11.1.2.0.0.0 | B7: Treasury Bills and Bonds | C7: =SUM(Investments!$P$54:Q54) -> 0 | D7: =SUM(Investments!$P$54:R54) -> 0 | E7: =SUM(Investments!$P$54:S54) -> 0 | F7: =SUM(Investments!$P$54:T54) -> 1558322.6
A8: 11.1.3.0.0.0 | B8: Securities and Investments | C8: 0 | D8: 0 | E8: 0 | F8: 0
A9: 11.1.4.0.0.0 | B9: Loans & Advances | C9: =SUM('NBD-MF-10-GA'!$C$10:D10) -> 3074055 | D9: =SUM('NBD-MF-10-GA'!$C$10:E10) -> 5873086 | E9: =SUM('NBD-MF-10-GA'!$C$10:F10) -> 10724627 | F9: =SUM('NBD-MF-10-GA'!$C$10:G10) -> 23684672
A10: 11.1.5.0.0.0 | B10: Others | C10: 0 | D10: 0 | E10: 0 | F10: 0
A11: 11.2.0.0.0.0 | B11: Interest Bearing Liabilities | C11: =SUM(C12:C14) -> 12031090 | D11: =SUM(D12:D14) -> 15911468 | E11: =SUM(E12:E14) -> 18951017 | F11: =SUM(F12:F14) -> 23110026
A12: 11.2.1.0.0.0 | B12: Deposits | C12: =SUM('NBD-MF-10-GA'!$C$16:D16) -> 342676 | D12: =SUM('NBD-MF-10-GA'!$C$16:E16) -> 925902 | E12: =SUM('NBD-MF-10-GA'!$C$16:F16) -> 2416500 | F12: =SUM('NBD-MF-10-GA'!$C$16:G16) -> 3273183
A13: 11.2.2.0.0.0 | B13: Borrowings | C13: =SUM('NBD-MF-10-GA'!$C$17:D17) -> 11688414 | D13: =SUM('NBD-MF-10-GA'!$C$17:E17) -> 14985566 | E13: =SUM('NBD-MF-10-GA'!$C$17:F17) -> 16534517 | F13: =SUM('NBD-MF-10-GA'!$C$17:G17) -> 19836843
A14: 11.2.3.0.0.0 | B14: Others | C14: 0 | D14: 0 | E14: 0 | F14: 0
A15: 11.3.0.0.0.0 | B15: Net Rate Sensitive Assets (Liabilities) (11.1.0.0.0-11.2.0.0.0) | C15: =C5-C11 -> -7931514.5 | D15: =D5-D11 -> -9012861.5 | E15: =E5-E11 -> -7200869.5 | F15: =F5-F11 -> 3158489.1
A16: 11.4.0.0.0.0 | B16: Interest Rate Sensitivity Ratio /2 (11.1.0.0.0/11.2.0.0.0)*100 | C16: =(C5/C11)*100 -> 34.074847 | D16: =(D5/D11)*100 -> 43.356192 | E16: =(E5/E11)*100 -> 62.002728 | F16: =(F5/F11)*100 -> 113.66718

Sheet NBD-MF-10-GA
A1: NBD-MF-10-GA:Maturity Gap Analysis
A2: Monthly Financial Return (LKR '000)
A4: Code | B4: Assets or Liability (a) | C4: Less than 7 Days (b) | D4: 7-30 Days (c) | E4: 1-3 Months (d) | F4: 3-6 Months (e) | G4: 6-12 Months (f) | H4: 1-3 Years (g) | I4: 3-5 Years (h) | J4: Over 5 Years (i) | K4: Unclassified (j) | L4: Total (i) | N4: As per BS | O4: Difference
A5: 10.1.0.0.0.0 | B5: Total Assets | C5: =SUM(C6:C13) -> 731166 | D5: =SUM(D6:D13) -> 4220210 | E5: =SUM(E6:E13) -> 3015841 | F5: =SUM(F6:F13) -> 4960490 | G5: =SUM(G6:G13) -> 14518368 | H5: =SUM(H6:H13) -> 29222012 | I5: =SUM(I6:I13) -> 7672126 | J5: =SUM(J6:J13) -> 604040 | K5: =SUM(K6:K13) -> 2641134 | L5: =SUM(C5:K5) -> 67585387 | N5: =SUM(N6:N13) -> 67585381 | O5: =L5-N5 -> 6 | P5: ='NBD-MF-01-SOFP'!D4 -> 67585381 | Q5: =N5-P6 -> 67585381
A6: 10.1.1.0.0.0 | B6: Cash | C6: ='NBD-MF-01-SOFP'!D6 -> 285966 | L6: =SUM(C6:K6) -> 285966 | N6: ='NBD-MF-01-SOFP'!D6 -> 285966 | O6: =L6-N6 -> 0 | P6: =N5-P5 -> 0
A7: 10.1.2.0.0.0 | B7: Due from Banks | C7: ='NBD-MF-01-SOFP'!D8+'NBD-MF-01-SOFP'!D9 -> 440349 | L7: =SUM(C7:K7) -> 440349 | N7: ='NBD-MF-01-SOFP'!D8+'NBD-MF-01-SOFP'!D9 -> 440349 | O7: =L7-N7 -> 0
A8: 10.1.3.0.0.0 | B8: Investments-Current | C8: =Investments!P83 -> 0 | D8: =Investments!Q83 -> 1025521 | E8: =Investments!R83-1 -> -1 | F8: =Investments!S83 -> 0 | G8: =Investments!T83 -> 1558323 | H8: =Investments!U83 -> 4588138 | I8: =Investments!V83 -> 351445 | J8: =Investments!W83 -> 491621 | K8: ='NBD-MF-01-SOFP'!D36 -> 195 | L8: =SUM(C8:K8) -> 8015242 | M8: Sasianet report to be discussed | N8: ='NBD-MF-01-SOFP'!D34+'NBD-MF-01-SOFP'!D11 -> 8015242 | O8: =L8-N8 -> 0
A9: 10.1.4.0.0.0 | B9: Investments-Non-performing/2 | L9: =SUM(C9:K9) -> 0 | O9: =L9-N9 -> 0
A10: 10.1.5.0.0.0 | B10: Loans & Advances - Current | C10: =Portfolio!C44 -> 4851 | D10: =Portfolio!D44 -> 3069204 | E10: =Portfolio!E44 -> 2799031 | F10: =Portfolio!F44 -> 4851541 | G10: =Portfolio!G44 -> 12960045 | H10: =Portfolio!H44 -> 24633874 | I10: =Portfolio!I44 -> 6722686 | J10: =Portfolio!J44 -> 112419 | L10: =SUM(C10:K10) -> 55153651
A11: 10.1.6.0.0.0 | B11: Loans & Advances - Non-performing/2 | K11: =Portfolio!K45 -> 2158174 | L11: =SUM(C11:K11) -> 2158174 | N11: ='NBD-MF-01-SOFP'!D45+'NBD-MF-01-SOFP'!D55 -> 57311824 | O11: =L10+L11-N11 -> 1
A12: 10.1.7.0.0.0 | B12: Fixed Assets | I12: ='NBD-MF-01-SOFP'!D75+'NBD-MF-01-SOFP'!D77+'NBD-MF-01-SOFP'!D84+'NBD-MF-01-SOFP'!D80 -> 569747 | K12: ='NBD-MF-01-SOFP'!D83+'NBD-MF-01-SOFP'!D69+'NBD-MF-01-SOFP'!D74 -> 482765 | L12: =SUM(C12:K12) -> 1052512 | N12: ='NBD-MF-01-SOFP'!D81+'NBD-MF-01-SOFP'!D80+'NBD-MF-01-SOFP'!D73+'NBD-MF-01-SOFP'!D69 -> 1052512 | O12: =L12-N12 -> 0
A13: 10.1.8.0.0.0 | B13: Other Assets | C13: ='Other Assets'!F122 -> 0 | D13: ='Other Assets'!G122 -> 125485 | E13: ='Other Assets'!H122 -> 216811 | F13: ='Other Assets'!I122 -> 108949 | G13: ='Other Assets'!J122 -> 0 | H13: ='Other Assets'!K122 -> 0 | I13: ='Other Assets'!L122 -> 28248 | K13: ='Other Assets'!N122 -> 0 | L13: =SUM(C13:K13) -> 479493 | N13: =SUM('NBD-MF-01-SOFP'!D87:D90) -> 479488 | O13: =L13-N13 -> 5
A14: 10.2.0.0.0.0 | B14: Total Liabilities | C14: =SUM(C15:C18) -> 3961034 | D14: =SUM(D15:D18) -> 12346067 | E14: =SUM(E15:E18) -> 4054805 | F14: =SUM(F15:F18) -> 3670855 | G14: =SUM(G15:G18) -> 4159009 | H14: =SUM(H15:H18) -> 19500416 | I14: =SUM(I15:I18) -> 2751215 | J14: =SUM(J15:J18) -> 207307 | K14: =SUM(K15:K18) -> 16934671 | L14: =SUM(C14:K14) -> 67585379 | N14: =SUM(N15:N18) -> 67585381 | O14: =L14-N14 -> -2 | Q14: =N14-P14 -> 67585381
A15: 10.2.1.0.0.0 | B15: Total Capital Fund | K15: ='NBD-MF-01-SOFP'!D133 -> 16934671 | L15: =SUM(C15:K15) -> 16934671 | N15: ='NBD-MF-01-SOFP'!D133 -> 16934671 | O15: =L15-N15 -> 0
A16: 10.2.2.0.0.0 | B16: Deposits | C16: =170661+21 -> 170682 | D16: 171994 | E16: 583226 | F16: 1490598 | G16: 856683 | H16: 6605625 | I16: 18717 | J16: 0 | K16: 0 | L16: =SUM(C16:K16) -> 9897525 | M16: Scienter report to be discussed | N16: ='NBD-MF-01-SOFP'!D99 -> 9897525 | O16: =L16-N16 -> 0
A17: 10.2.3.0.0.0 | B17: Borrowings | C17: ='NBD-MF-01-SOFP'!D93+Borrowings!N3 -> 3790352 | D17: =Borrowings!N4 -> 7898062 | E17: =Borrowings!N5 -> 3297152 | F17: =Borrowings!N6 -> 1548951 | G17: =Borrowings!N7 -> 3302326 | H17: =Borrowings!N8 -> 12837779 | I17: =Borrowings!N9 -> 2732498 | J17: =Borrowings!N10 -> 0 | K17: 0 | L17: =SUM(C17:K17) -> 35407120 | M17: Sasianet report to be discussed | N17: ='NBD-MF-01-SOFP'!D92+'NBD-MF-01-SOFP'!D125+Borrowings!N19 -> 35407120 | O17: =L17-N17 -> 0
A18: 10.2.4.0.0.0 | B18: Other Liabilities | C18: ='Other Liabilities'!F163 -> 0 | D18: ='Other Liabilities'!G163 -> 4276011 | E18: ='Other Liabilities'!H163 -> 174427 | F18: ='Other Liabilities'!I163 -> 631306 | G18: ='Other Liabilities'!J163 -> 0 | H18: ='Other Liabilities'!K163 -> 57012 | I18: ='Other Liabilities'!L163 -> 0 | J18: ='Other Liabilities'!M163 -> 207307 | K18: ='Other Liabilities'!N163 -> 0 | L18: =SUM(C18:K18) -> 5346063 | N18: =SUM('NBD-MF-01-SOFP'!D127:D132)-Borrowings!N19 -> 5346065 | O18: =L18-N18 -> -2
A19: 10.3.4.0.0.0 | B19: Maturity Gap (10.1.0.0.0-10.2.0.0.0) | C19: =C5-C14 -> -3229868 | D19: =D5-D14 -> -8125857 | E19: =E5-E14 -> -1038964 | F19: =F5-F14 -> 1289635 | G19: =G5-G14 -> 10359359 | H19: =H5-H14 -> 9721596 | I19: =I5-I14 -> 4920911 | J19: =J5-J14 -> 396733 | K19: =K5-K14 -> -14293537 | L19: =SUM(C19:K19) -> 8
A20: 10.4.4.0.0.0 | B20: Cumulative Gap | C20: =C19 -> -3229868 | D20: =SUM(C19:D19) -> -11355725 | E20: =SUM(C19:E19) -> -12394689 | F20: =SUM(C19:F19) -> -11105054 | G20: =SUM(C19:G19) -> -745695 | H20: =SUM(C19:H19) -> 8975901 | I20: =SUM(C19:I19) -> 13896812 | J20: =SUM(C19:J19) -> 14293545 | K20: =SUM(C19:K19) -> 8 | L20: =L5-L14 -> 8
F23: TA | G23: =SUM(C5:G5) -> 27446075 | H23: =H5 -> 29222012 | I23: =I5 -> 7672126 | J23: =J5 -> 604040
F24: TL | G24: =SUM(C14:G14) -> 28191770 | H24: =H14 -> 19500416 | I24: =I14 -> 2751215 | J24: =J14 -> 207307
G25: =G23/G24 -> 0.9735492
D27: Short Term | E27: =SUM(C17:G17) -> 19836843 | F27: =E27/E29 -> 0.56025011
D28: Long Term | E28: =SUM(H17:J17) -> 15570277 | F28: =E28/E29 -> 0.43974989
E29: =SUM(E27:E28) -> 35407120
E31: =SUM(C5:G5) -> 27446075
E32: =SUM(C14:G14) -> 28191770 | F32: =E31/E32 -> 0.9735492

Sheet Upload
A1: CSV_NBD-MF-11-IS | F1: CSV_NBD-MF-10-GA
A2: =ROUND('NBD-MF-11-IS'!C5,0) -> 4099576 | B2: =ROUND('NBD-MF-11-IS'!D5,0) -> 6898607 | C2: =ROUND('NBD-MF-11-IS'!E5,0) -> 11750148 | D2: =ROUND('NBD-MF-11-IS'!F5,0) -> 26268515 | F2: =ROUND('NBD-MF-10-GA'!C5,0) -> 731166 | G2: =ROUND('NBD-MF-10-GA'!D5,0) -> 4220210 | H2: =ROUND('NBD-MF-10-GA'!E5,0) -> 3015841 | I2: =ROUND('NBD-MF-10-GA'!F5,0) -> 4960490 | J2: =ROUND('NBD-MF-10-GA'!G5,0) -> 14518368 | K2: =ROUND('NBD-MF-10-GA'!H5,0) -> 29222012 | L2: =ROUND('NBD-MF-10-GA'!I5,0) -> 7672126 | M2: =ROUND('NBD-MF-10-GA'!J5,0) -> 604040 | ... O2: =ROUND('NBD-MF-10-GA'!L5,0) -> 67585387
A3: =ROUND('NBD-MF-11-IS'!C6,0) -> 1025521 | B3: =ROUND('NBD-MF-11-IS'!D6,0) -> 1025521 | C3: =ROUND('NBD-MF-11-IS'!E6,0) -> 1025521 | D3: =ROUND('NBD-MF-11-IS'!F6,0) -> 1025521 | F3: =ROUND('NBD-MF-10-GA'!C6,0) -> 285966 | G3: =ROUND('NBD-MF-10-GA'!D6,0) -> 0 | H3: =ROUND('NBD-MF-10-GA'!E6,0) -> 0 | I3: =ROUND('NBD-MF-10-GA'!F6,0) -> 0 | J3: =ROUND('NBD-MF-10-GA'!G6,0) -> 0 | K3: =ROUND('NBD-MF-10-GA'!H6,0) -> 0 | L3: =ROUND('NBD-MF-10-GA'!I6,0) -> 0 | M3: =ROUND('NBD-MF-10-GA'!J6,0) -> 0 | ... O3: =ROUND('NBD-MF-10-GA'!L6,0) -> 285966
A4: =ROUND('NBD-MF-11-IS'!C6,0) -> 1025521 | B4: =ROUND('NBD-MF-11-IS'!D6,0) -> 1025521 | C4: =ROUND('NBD-MF-11-IS'!E6,0) -> 1025521 | D4: =ROUND('NBD-MF-11-IS'!F7,0) -> 1558323 | F4: =ROUND('NBD-MF-10-GA'!C7,0) -> 440349 | G4: =ROUND('NBD-MF-10-GA'!D7,0) -> 0 | H4: =ROUND('NBD-MF-10-GA'!E7,0) -> 0 | I4: =ROUND('NBD-MF-10-GA'!F7,0) -> 0 | J4: =ROUND('NBD-MF-10-GA'!G7,0) -> 0 | K4: =ROUND('NBD-MF-10-GA'!H7,0) -> 0 | L4: =ROUND('NBD-MF-10-GA'!I7,0) -> 0 | M4: =ROUND('NBD-MF-10-GA'!J7,0) -> 0 | ... O4: =ROUND('NBD-MF-10-GA'!L7,0) -> 440349
A5: =ROUND('NBD-MF-11-IS'!C8,0) -> 0 | B5: =ROUND('NBD-MF-11-IS'!D8,0) -> 0 | C5: =ROUND('NBD-MF-11-IS'!E8,0) -> 0 | D5: =ROUND('NBD-MF-11-IS'!F8,0) -> 0 | F5: =ROUND('NBD-MF-10-GA'!C8,0) -> 0 | G5: =ROUND('NBD-MF-10-GA'!D8,0) -> 1025521 | H5: =ROUND('NBD-MF-10-GA'!E8,0) -> -1 | I5: =ROUND('NBD-MF-10-GA'!F8,0) -> 0 | J5: =ROUND('NBD-MF-10-GA'!G8,0) -> 1558323 | K5: =ROUND('NBD-MF-10-GA'!H8,0) -> 4588138 | L5: =ROUND('NBD-MF-10-GA'!I8,0) -> 351445 | M5: =ROUND('NBD-MF-10-GA'!J8,0) -> 491621 | ... O5: =ROUND('NBD-MF-10-GA'!L8,0) -> 8015242
A6: =ROUND('NBD-MF-11-IS'!C9,0) -> 3074055 | B6: =ROUND('NBD-MF-11-IS'!D9,0) -> 5873086 | C6: =ROUND('NBD-MF-11-IS'!E9,0) -> 10724627 | D6: =ROUND('NBD-MF-11-IS'!F9,0) -> 23684672 | F6: =ROUND('NBD-MF-10-GA'!C9,0) -> 0 | G6: =ROUND('NBD-MF-10-GA'!D9,0) -> 0 | H6: =ROUND('NBD-MF-10-GA'!E9,0) -> 0 | I6: =ROUND('NBD-MF-10-GA'!F9,0) -> 0 | J6: =ROUND('NBD-MF-10-GA'!G9,0) -> 0 | K6: =ROUND('NBD-MF-10-GA'!H9,0) -> 0 | L6: =ROUND('NBD-MF-10-GA'!I9,0) -> 0 | M6: =ROUND('NBD-MF-10-GA'!J9,0) -> 0 | ... O6: =ROUND('NBD-MF-10-GA'!L9,0) -> 0
A7: =ROUND('NBD-MF-11-IS'!C10,0) -> 0 | B7: =ROUND('NBD-MF-11-IS'!D10,0) -> 0 | C7: =ROUND('NBD-MF-11-IS'!E10,0) -> 0 | D7: =ROUND('NBD-MF-11-IS'!F10,0) -> 0 | F7: =ROUND('NBD-MF-10-GA'!C10,0) -> 4851 | G7: =ROUND('NBD-MF-10-GA'!D10,0) -> 3069204 | H7: =ROUND('NBD-MF-10-GA'!E10,0) -> 2799031 | I7: =ROUND('NBD-MF-10-GA'!F10,0) -> 4851541 | J7: =ROUND('NBD-MF-10-GA'!G10,0) -> 12960045 | K7: =ROUND('NBD-MF-10-GA'!H10,0) -> 24633874 | L7: =ROUND('NBD-MF-10-GA'!I10,0) -> 6722686 | M7: =ROUND('NBD-MF-10-GA'!J10,0) -> 112419 | ... O7: =ROUND('NBD-MF-10-GA'!L10,0) -> 55153651
A8: =ROUND('NBD-MF-11-IS'!C11,0) -> 12031090 | B8: =ROUND('NBD-MF-11-IS'!D11,0) -> 15911468 | C8: =ROUND('NBD-MF-11-IS'!E11,0) -> 18951017 | D8: =ROUND('NBD-MF-11-IS'!F11,0) -> 23110026 | F8: =ROUND('NBD-MF-10-GA'!C11,0) -> 0 | G8: =ROUND('NBD-MF-10-GA'!D11,0) -> 0 | H8: =ROUND('NBD-MF-10-GA'!E11,0) -> 0 | I8: =ROUND('NBD-MF-10-GA'!F11,0) -> 0 | J8: =ROUND('NBD-MF-10-GA'!G11,0) -> 0 | K8: =ROUND('NBD-MF-10-GA'!H11,0) -> 0 | L8: =ROUND('NBD-MF-10-GA'!I11,0) -> 0 | M8: =ROUND('NBD-MF-10-GA'!J11,0) -> 0 | ... O8: =ROUND('NBD-MF-10-GA'!L11,0) -> 2158174
A9: =ROUND('NBD-MF-11-IS'!C12,0) -> 342676 | B9: =ROUND('NBD-MF-11-IS'!D12,0) -> 925902 | C9: =ROUND('NBD-MF-11-IS'!E12,0) -> 2416500 | D9: =ROUND('NBD-MF-11-IS'!F12,0) -> 3273183 | F9: =ROUND('NBD-MF-10-GA'!C12,0) -> 0 | G9: =ROUND('NBD-MF-10-GA'!D12,0) -> 0 | H9: =ROUND('NBD-MF-10-GA'!E12,0) -> 0 | I9: =ROUND('NBD-MF-10-GA'!F12,0) -> 0 | J9: =ROUND('NBD-MF-10-GA'!G12,0) -> 0 | K9: =ROUND('NBD-MF-10-GA'!H12,0) -> 0 | L9: =ROUND('NBD-MF-10-GA'!I12,0) -> 569747 | M9: =ROUND('NBD-MF-10-GA'!J12,0) -> 0 | ... O9: =ROUND('NBD-MF-10-GA'!L12,0) -> 1052512
A10: =ROUND('NBD-MF-11-IS'!C13,0) -> 11688414 | B10: =ROUND('NBD-MF-11-IS'!D13,0) -> 14985566 | C10: =ROUND('NBD-MF-11-IS'!E13,0) -> 16534517 | D10: =ROUND('NBD-MF-11-IS'!F13,0) -> 19836843 | F10: =ROUND('NBD-MF-10-GA'!C13,0) -> 0 | G10: =ROUND('NBD-MF-10-GA'!D13,0) -> 125485 | H10: =ROUND('NBD-MF-10-GA'!E13,0) -> 216811 | I10: =ROUND('NBD-MF-10-GA'!F13,0) -> 108949 | J10: =ROUND('NBD-MF-10-GA'!G13,0) -> 0 | K10: =ROUND('NBD-MF-10-GA'!H13,0) -> 0 | L10: =ROUND('NBD-MF-10-GA'!I13,0) -> 28248 | M10: =ROUND('NBD-MF-10-GA'!J13,0) -> 0 | ... O10: =ROUND('NBD-MF-10-GA'!L13,0) -> 479493
A11: =ROUND('NBD-MF-11-IS'!C14,0) -> 0 | B11: =ROUND('NBD-MF-11-IS'!D14,0) -> 0 | C11: =ROUND('NBD-MF-11-IS'!E14,0) -> 0 | D11: =ROUND('NBD-MF-11-IS'!F14,0) -> 0 | F11: =ROUND('NBD-MF-10-GA'!C14,0) -> 3961034 | G11: =ROUND('NBD-MF-10-GA'!D14,0) -> 12346067 | H11: =ROUND('NBD-MF-10-GA'!E14,0) -> 4054805 | I11: =ROUND('NBD-MF-10-GA'!F14,0) -> 3670855 | J11: =ROUND('NBD-MF-10-GA'!G14,0) -> 4159009 | K11: =ROUND('NBD-MF-10-GA'!H14,0) -> 19500416 | L11: =ROUND('NBD-MF-10-GA'!I14,0) -> 2751215 | M11: =ROUND('NBD-MF-10-GA'!J14,0) -> 207307 | ... O11: =ROUND('NBD-MF-10-GA'!L14,0) -> 67585379
A12: =ROUND('NBD-MF-11-IS'!C15,0) -> -7931514 | B12: =ROUND('NBD-MF-11-IS'!D15,0) -> -9012861 | C12: =ROUND('NBD-MF-11-IS'!E15,0) -> -7200869 | D12: =ROUND('NBD-MF-11-IS'!F15,0) -> 3158489 | F12: =ROUND('NBD-MF-10-GA'!C15,0) -> 0 | G12: =ROUND('NBD-MF-10-GA'!D15,0) -> 0 | H12: =ROUND('NBD-MF-10-GA'!E15,0) -> 0 | I12: =ROUND('NBD-MF-10-GA'!F15,0) -> 0 | J12: =ROUND('NBD-MF-10-GA'!G15,0) -> 0 | K12: =ROUND('NBD-MF-10-GA'!H15,0) -> 0 | L12: =ROUND('NBD-MF-10-GA'!I15,0) -> 0 | M12: =ROUND('NBD-MF-10-GA'!J15,0) -> 0 | ... O12: =ROUND('NBD-MF-10-GA'!L15,0) -> 16934671
A13: =ROUND('NBD-MF-11-IS'!C16,0) -> 34 | B13: =ROUND('NBD-MF-11-IS'!D16,0) -> 43 | C13: =ROUND('NBD-MF-11-IS'!E16,0) -> 62 | D13: =ROUND('NBD-MF-11-IS'!F16,0) -> 114 | F13: =ROUND('NBD-MF-10-GA'!C16,0) -> 170682 | G13: =ROUND('NBD-MF-10-GA'!D16,0) -> 171994 | H13: =ROUND('NBD-MF-10-GA'!E16,0) -> 583226 | I13: =ROUND('NBD-MF-10-GA'!F16,0) -> 1490598 | J13: =ROUND('NBD-MF-10-GA'!G16,0) -> 856683 | K13: =ROUND('NBD-MF-10-GA'!H16,0) -> 6605625 | L13: =ROUND('NBD-MF-10-GA'!I16,0) -> 18717 | M13: =ROUND('NBD-MF-10-GA'!J16,0) -> 0 | ... O13: =ROUND('NBD-MF-10-GA'!L16,0) -> 9897525
F14: =ROUND('NBD-MF-10-GA'!C17,0) -> 3790352 | G14: =ROUND('NBD-MF-10-GA'!D17,0) -> 7898062 | H14: =ROUND('NBD-MF-10-GA'!E17,0) -> 3297152 | I14: =ROUND('NBD-MF-10-GA'!F17,0) -> 1548951 | J14: =ROUND('NBD-MF-10-GA'!G17,0) -> 3302326 | K14: =ROUND('NBD-MF-10-GA'!H17,0) -> 12837779 | L14: =ROUND('NBD-MF-10-GA'!I17,0) -> 2732498 | M14: =ROUND('NBD-MF-10-GA'!J17,0) -> 0 | ... O14: =ROUND('NBD-MF-10-GA'!L17,0) -> 35407120
F15: =ROUND('NBD-MF-10-GA'!C18,0) -> 0 | G15: =ROUND('NBD-MF-10-GA'!D18,0) -> 4276011 | H15: =ROUND('NBD-MF-10-GA'!E18,0) -> 174427 | I15: =ROUND('NBD-MF-10-GA'!F18,0) -> 631306 | J15: =ROUND('NBD-MF-10-GA'!G18,0) -> 0 | K15: =ROUND('NBD-MF-10-GA'!H18,0) -> 57012 | L15: =ROUND('NBD-MF-10-GA'!I18,0) -> 0 | M15: =ROUND('NBD-MF-10-GA'!J18,0) -> 207307 | ... O15: =ROUND('NBD-MF-10-GA'!L18,0) -> 5346063
F16: =ROUND('NBD-MF-10-GA'!C19,0) -> -3229868 | G16: =ROUND('NBD-MF-10-GA'!D19,0) -> -8125857 | H16: =ROUND('NBD-MF-10-GA'!E19,0) -> -1038964 | I16: =ROUND('NBD-MF-10-GA'!F19,0) -> 1289635 | J16: =ROUND('NBD-MF-10-GA'!G19,0) -> 10359359 | K16: =ROUND('NBD-MF-10-GA'!H19,0) -> 9721596 | L16: =ROUND('NBD-MF-10-GA'!I19,0) -> 4920911 | M16: =ROUND('NBD-MF-10-GA'!J19,0) -> 396733 | ... O16: =ROUND('NBD-MF-10-GA'!L19,0) -> 8
F17: =ROUND('NBD-MF-10-GA'!C20,0) -> -3229868 | G17: =ROUND('NBD-MF-10-GA'!D20,0) -> -11355725 | H17: =ROUND('NBD-MF-10-GA'!E20,0) -> -12394689 | I17: =ROUND('NBD-MF-10-GA'!F20,0) -> -11105054 | J17: =ROUND('NBD-MF-10-GA'!G20,0) -> -745695 | K17: =ROUND('NBD-MF-10-GA'!H20,0) -> 8975901 | L17: =ROUND('NBD-MF-10-GA'!I20,0) -> 13896812 | M17: =ROUND('NBD-MF-10-GA'!J20,0) -> 14293545 | ... O17: =ROUND('NBD-MF-10-GA'!L20,0) -> 8

Sheet Investments
K1: 1000 | P1: Less than 7 Days | Q1: 7-30 Days | R1: 1-3 Months | S1: 3-6 Months | T1: 6-12 Months | U1: 1-3 Years | V1: 3-5 Years | W1: Over 5 Years | X1: Total
A2: Treasury Bonds | B2: ISIN | C2: Cost | E2: Rate | F2: Date of Investment | G2: Date of Maturity | H2: Coupon | I2: Face Value | J2: Value As per IFRSs | K2: M2M Gain/(Loss) | L2: Total | M2: ='NBD-MF-01-SOFP'!D2 -> 45900 | N2: Bucket
A3: National Development Bank PLC | B3: LKB00931E153 | C3: 45576.7 | E3: 0.2016 | F3: 44743 | G3: 47983 | H3: 0.18 | I3: 50000 | J3: 46382.75 | K3: 20458.902 | L3: =J3+K3 -> 66841.652 | M3: =(G3-$M$2) -> 2083 | N3: =VLOOKUP(M3,T!$A$12:$C$19,3,TRUE) -> Over 5 Years | P3: =IF(P$1=$N3,$L3,0) -> 0 | Q3: =IF(Q$1=$N3,$L3,0) -> 0 | R3: =IF(R$1=$N3,$L3,0) -> 0 | S3: =IF(S$1=$N3,$L3,0) -> 0 | T3: =IF(T$1=$N3,$L3,0) -> 0 | U3: =IF(U$1=$N3,$L3,0) -> 0 | V3: =IF(V$1=$N3,$L3,0) -> 0 | W3: =IF(W$1=$N3,$L3,0) -> 66841.652 | X3: =SUM(P3:W3) -> 66841.652
A4: National Development Bank PLC | B4: LKB00931E153 | C4: 45238.1 | E4: 0.2034 | F4: 44743 | G4: 47983 | H4: 0.18 | I4: 50000 | J4: 46101.55 | K4: 20740.217 | L4: =J4+K4 -> 66841.767 | M4: =(G4-$M$2) -> 2083 | N4: =VLOOKUP(M4,T!$A$12:$C$19,3,TRUE) -> Over 5 Years | P4: =IF(P$1=$N4,$L4,0) -> 0 | Q4: =IF(Q$1=$N4,$L4,0) -> 0 | R4: =IF(R$1=$N4,$L4,0) -> 0 | S4: =IF(S$1=$N4,$L4,0) -> 0 | T4: =IF(T$1=$N4,$L4,0) -> 0 | U4: =IF(U$1=$N4,$L4,0) -> 0 | V4: =IF(V$1=$N4,$L4,0) -> 0 | W4: =IF(W$1=$N4,$L4,0) -> 66841.767 | X4: =SUM(P4:W4) -> 66841.767
A5: National Development Bank PLC | B5: LKB00931E153 | C5: 45014.543 | E5: 0.2046 | F5: 44743 | G5: 47983 | H5: 0.18 | I5: 50000 | J5: 45915.4 | K5: 20926.426 | L5: =J5+K5 -> 66841.826 | M5: =(G5-$M$2) -> 2083 | N5: =VLOOKUP(M5,T!$A$12:$C$19,3,TRUE) -> Over 5 Years | P5: =IF(P$1=$N5,$L5,0) -> 0 | Q5: =IF(Q$1=$N5,$L5,0) -> 0 | R5: =IF(R$1=$N5,$L5,0) -> 0 | S5: =IF(S$1=$N5,$L5,0) -> 0 | T5: =IF(T$1=$N5,$L5,0) -> 0 | U5: =IF(U$1=$N5,$L5,0) -> 0 | V5: =IF(V$1=$N5,$L5,0) -> 0 | W5: =IF(W$1=$N5,$L5,0) -> 66841.826 | X5: =SUM(P5:W5) -> 66841.826
A6: National Development Bank PLC | B6: LKB00931E153 | C6: 44737.45 | E6: 0.2061 | F6: 44743 | G6: 47983 | H6: 0.18 | I6: 50000 | J6: 45684.2 | K6: 21157.7 | L6: =J6+K6 -> 66841.9 | M6: =(G6-$M$2) -> 2083 | N6: =VLOOKUP(M6,T!$A$12:$C$19,3,TRUE) -> Over 5 Years | P6: =IF(P$1=$N6,$L6,0) -> 0 | Q6: =IF(Q$1=$N6,$L6,0) -> 0 | R6: =IF(R$1=$N6,$L6,0) -> 0 | S6: =IF(S$1=$N6,$L6,0) -> 0 | T6: =IF(T$1=$N6,$L6,0) -> 0 | U6: =IF(U$1=$N6,$L6,0) -> 0 | V6: =IF(V$1=$N6,$L6,0) -> 0 | W6: =IF(W$1=$N6,$L6,0) -> 66841.9 | X6: =SUM(P6:W6) -> 66841.9
A7: National Development Bank PLC | B7: LKB00931E153 | C7: 44281.493 | E7: 0.2086 | F7: 44743 | G7: 47983 | H7: 0.18 | I7: 50000 | J7: 45302.55 | K7: 21539.516 | L7: =J7+K7 -> 66842.066 | M7: =(G7-$M$2) -> 2083 | N7: =VLOOKUP(M7,T!$A$12:$C$19,3,TRUE) -> Over 5 Years | P7: =IF(P$1=$N7,$L7,0) -> 0 | Q7: =IF(Q$1=$N7,$L7,0) -> 0 | R7: =IF(R$1=$N7,$L7,0) -> 0 | S7: =IF(S$1=$N7,$L7,0) -> 0 | T7: =IF(T$1=$N7,$L7,0) -> 0 | U7: =IF(U$1=$N7,$L7,0) -> 0 | V7: =IF(V$1=$N7,$L7,0) -> 0 | W7: =IF(W$1=$N7,$L7,0) -> 66842.066 | X7: =SUM(P7:W7) -> 66842.066
A8: National Development Bank PLC | B8: LKB00628A153 | C8: 44967.6 | E8: 0.211577 | F8: 44743 | G8: 46767 | H8: 0.18 | I8: 50000 | J8: 47128.65 | K8: 12553.251 | L8: =J8+K8 -> 59681.901 | M8: =(G8-$M$2) -> 867 | N8: =VLOOKUP(M8,T!$A$12:$C$19,3,TRUE) -> 1-3 Years | P8: =IF(P$1=$N8,$L8,0) -> 0 | Q8: =IF(Q$1=$N8,$L8,0) -> 0 | R8: =IF(R$1=$N8,$L8,0) -> 0 | S8: =IF(S$1=$N8,$L8,0) -> 0 | T8: =IF(T$1=$N8,$L8,0) -> 0 | U8: =IF(U$1=$N8,$L8,0) -> 59681.901 | V8: =IF(V$1=$N8,$L8,0) -> 0 | W8: =IF(W$1=$N8,$L8,0) -> 0 | X8: =SUM(P8:W8) -> 59681.901
A9: National Development Bank PLC | B9: LKB00628A153 | C9: 89523.8 | E9: 0.212977 | F9: 44743 | G9: 46767 | H9: 0.18 | I9: 100000 | J9: 94016.1 | K9: 25348.028 | L9: =J9+K9 -> 119364.13 | M9: =(G9-$M$2) -> 867 | N9: =VLOOKUP(M9,T!$A$12:$C$19,3,TRUE) -> 1-3 Years | P9: =IF(P$1=$N9,$L9,0) -> 0 | Q9: =IF(Q$1=$N9,$L9,0) -> 0 | R9: =IF(R$1=$N9,$L9,0) -> 0 | S9: =IF(S$1=$N9,$L9,0) -> 0 | T9: =IF(T$1=$N9,$L9,0) -> 0 | U9: =IF(U$1=$N9,$L9,0) -> 119364.13 | V9: =IF(V$1=$N9,$L9,0) -> 0 | W9: =IF(W$1=$N9,$L9,0) -> 0 | X9: =SUM(P9:W9) -> 119364.13
A10: National Development Bank PLC | B10: LKB00628A153 | C10: 89115.1 | E10: 0.214376 | F10: 44743 | G10: 46767 | H10: 0.18 | I10: 100000 | J10: 93775.8 | K10: 25588.555 | L10: =J10+K10 -> 119364.35 | M10: =(G10-$M$2) -> 867 | N10: =VLOOKUP(M10,T!$A$12:$C$19,3,TRUE) -> 1-3 Years | P10: =IF(P$1=$N10,$L10,0) -> 0 | Q10: =IF(Q$1=$N10,$L10,0) -> 0 | R10: =IF(R$1=$N10,$L10,0) -> 0 | S10: =IF(S$1=$N10,$L10,0) -> 0 | T10: =IF(T$1=$N10,$L10,0) -> 0 | U10: =IF(U$1=$N10,$L10,0) -> 119364.35 | V10: =IF(V$1=$N10,$L10,0) -> 0 | W10: =IF(W$1=$N10,$L10,0) -> 0 | X10: =SUM(P10:W10) -> 119364.35
A11: National Development Bank PLC | B11: LKB00628A153 | C11: 79751.5 | E11: 0.2497 | F11: 44763 | G11: 46767 | H11: 0.18 | I11: 100000 | J11: 87972.3 | K11: 31398.28 | L11: =J11+K11 -> 119370.58 | M11: =(G11-$M$2) -> 867 | N11: =VLOOKUP(M11,T!$A$12:$C$19,3,TRUE) -> 1-3 Years | P11: =IF(P$1=$N11,$L11,0) -> 0 | Q11: =IF(Q$1=$N11,$L11,0) -> 0 | R11: =IF(R$1=$N11,$L11,0) -> 0 | S11: =IF(S$1=$N11,$L11,0) -> 0 | T11: =IF(T$1=$N11,$L11,0) -> 0 | U11: =IF(U$1=$N11,$L11,0) -> 119370.58 | V11: =IF(V$1=$N11,$L11,0) -> 0 | W11: =IF(W$1=$N11,$L11,0) -> 0 | X11: =SUM(P11:W11) -> 119370.58
A12: National Development Bank PLC | B12: LKB00729G156 | C12: 78552.7 | E12: 0.2697 | F12: 44763 | G12: 47314 | H12: 0.2 | I12: 100000 | J12: 83746.8 | K12: 50046.054 | L12: =J12+K12 -> 133792.85 | M12: =(G12-$M$2) -> 1414 | N12: =VLOOKUP(M12,T!$A$12:$C$19,3,TRUE) -> 3-5 Years | P12: =IF(P$1=$N12,$L12,0) -> 0 | Q12: =IF(Q$1=$N12,$L12,0) -> 0 | R12: =IF(R$1=$N12,$L12,0) -> 0 | S12: =IF(S$1=$N12,$L12,0) -> 0 | T12: =IF(T$1=$N12,$L12,0) -> 0 | U12: =IF(U$1=$N12,$L12,0) -> 0 | V12: =IF(V$1=$N12,$L12,0) -> 133792.85 | W12: =IF(W$1=$N12,$L12,0) -> 0 | X12: =SUM(P12:W12) -> 133792.85
A13: National Development Bank PLC | B13: LKB00931E153 | C13: 34718.592 | E13: 0.272806 | F13: 44774 | G13: 47983 | H13: 0.18 | I13: 50000 | J13: 36878.95 | K13: 29965.582 | L13: =J13+K13 -> 66844.532 | M13: =(G13-$M$2) -> 2083 | N13: =VLOOKUP(M13,T!$A$12:$C$19,3,TRUE) -> Over 5 Years | P13: =IF(P$1=$N13,$L13,0) -> 0 | Q13: =IF(Q$1=$N13,$L13,0) -> 0 | R13: =IF(R$1=$N13,$L13,0) -> 0 | S13: =IF(S$1=$N13,$L13,0) -> 0 | T13: =IF(T$1=$N13,$L13,0) -> 0 | U13: =IF(U$1=$N13,$L13,0) -> 0 | V13: =IF(V$1=$N13,$L13,0) -> 0 | W13: =IF(W$1=$N13,$L13,0) -> 66844.532 | X13: =SUM(P13:W13) -> 66844.532
A14: National Development Bank PLC | B14: LKB00931E153 | C14: 33938.442 | E14: 0.279306 | F14: 44774 | G14: 47983 | H14: 0.18 | I14: 50000 | J14: 36155.75 | K14: 30688.933 | L14: =J14+K14 -> 66844.683 | M14: =(G14-$M$2) -> 2083 | N14: =VLOOKUP(M14,T!$A$12:$C$19,3,TRUE) -> Over 5 Years | P14: =IF(P$1=$N14,$L14,0) -> 0 | Q14: =IF(Q$1=$N14,$L14,0) -> 0 | R14: =IF(R$1=$N14,$L14,0) -> 0 | S14: =IF(S$1=$N14,$L14,0) -> 0 | T14: =IF(T$1=$N14,$L14,0) -> 0 | U14: =IF(U$1=$N14,$L14,0) -> 0 | V14: =IF(V$1=$N14,$L14,0) -> 0 | W14: =IF(W$1=$N14,$L14,0) -> 66844.683 | X14: =SUM(P14:W14) -> 66844.683
... A45: Capital Alliance PLC | B45: LKB00527I150 | C45: 196918.75 | E45: 0.287202 | F45: 45016 | G45: 46645 | H45: 0.2 | I45: 250000 | J45: 217957.75 | K45: 84567.658 | L45: =J45+K45 -> 302525.41 | M45: =(G45-$M$2) -> 745 | N45: =VLOOKUP(M45,T!$A$12:$C$19,3,TRUE) -> 1-3 Years | P45: =IF(P$1=$N45,$L45,0) -> 0 | Q45: =IF(Q$1=$N45,$L45,0) -> 0 | R45: =IF(R$1=$N45,$L45,0) -> 0 | S45: =IF(S$1=$N45,$L45,0) -> 0 | T45: =IF(T$1=$N45,$L45,0) -> 0 | U45: =IF(U$1=$N45,$L45,0) -> 302525.41 | V45: =IF(V$1=$N45,$L45,0) -> 0 | W45: =IF(W$1=$N45,$L45,0) -> 0 | X45: =SUM(P45:W45) -> 302525.41
C51: =SUM(C3:C50) -> 3886559.7 | I51: =SUM(I3:I50) -> 4951191.7 | J51: =SUM(J3:J50) -> 4374337.5 | K51: =SUM(K3:K50) -> 1421673.8 | L51: =SUM(L3:L50) -> 5796011.3 | P51: =SUM(P3:P50) -> 0 | Q51: =SUM(Q3:Q50) -> 0 | R51: =SUM(R3:R50) -> 0 | S51: =SUM(S3:S50) -> 0 | T51: =SUM(T3:T50) -> 1483128.6 | U51: =SUM(U3:U50) -> 3510497.9 | V51: =SUM(V3:V50) -> 334486.36 | W51: =SUM(W3:W50) -> 467898.43 | X51: =SUM(X3:X50) -> 5796011.3 | Y51: =X51-L51 -> 0
A52: Interest receivable | L52: 293855.37 | P52: =P51/$X$51*$L$52 -> 0 | Q52: =Q51/$X$51*$L$52 -> 0 | R52: =R51/$X$51*$L$52 -> 0 | S52: =S51/$X$51*$L$52 -> 0 | T52: =T51/$X$51*$L$52 -> 75194.004 | U52: =U51/$X$51*$L$52 -> 177980.79 | V52: =V51/$X$51*$L$52 -> 16958.32 | W52: =W51/$X$51*$L$52 -> 23722.256 | X52: =SUM(P52:W52) -> 293855.37
A53: Provision for Impairment | L53: 0 | P53: =P51/$X$51*$L$53 -> 0 | Q53: =Q51/$X$51*$L$53 -> 0 | R53: =R51/$X$51*$L$53 -> 0 | S53: =S51/$X$51*$L$53 -> 0 | T53: =T51/$X$51*$L$53 -> 0 | U53: =U51/$X$51*$L$53 -> 0 | V53: =V51/$X$51*$L$53 -> 0 | W53: =W51/$X$51*$L$53 -> 0 | X53: =X51/$X$51*$L$53 -> 0
A54: Total | L54: =SUM(L51:L53) -> 6089866.7 | P54: =SUM(P51:P53) -> 0 | Q54: =SUM(Q51:Q53) -> 0 | R54: =SUM(R51:R53) -> 0 | S54: =SUM(S51:S53) -> 0 | T54: =SUM(T51:T53) -> 1558322.6 | U54: =SUM(U51:U53) -> 3688478.7 | V54: =SUM(V51:V53) -> 351444.68 | W54: =SUM(W51:W53) -> 491620.68 | X54: =SUM(X51:X53) -> 6089866.7
A57: Fixed Deposits
A58: Institution | B58: Reference Number | C58: Currency | E58: Rate | F58: Date of Investment | G58: Date of Maturity | H58: Value in USD | I58: Value in LKR (000) | L58: Total | M58: Days
A59: Nations Trust Bank | B59: PI20241129-124 | C59: USD | E59: 0.056 | F59: 45566 | G59: 46316 | H59: 750000 | I59: 219651.98 | L59: =SUM(I59:K59) -> 219651.98 | M59: =(G59-$M$2) -> 416 | N59: =VLOOKUP(M59,T!$A$12:$C$19,3,TRUE) -> 1-3 Years | P59: =IF(P$1=$N59,$L59,0) -> 0 | Q59: =IF(Q$1=$N59,$L59,0) -> 0 | R59: =IF(R$1=$N59,$L59,0) -> 0 | S59: =IF(S$1=$N59,$L59,0) -> 0 | T59: =IF(T$1=$N59,$L59,0) -> 0 | U59: =IF(U$1=$N59,$L59,0) -> 219651.98 | V59: =IF(V$1=$N59,$L59,0) -> 0 | W59: =IF(W$1=$N59,$L59,0) -> 0 | X59: =SUM(P59:W59) -> 219651.98
A60: Nations Trust Bank | B60: PI20241129-125 | C60: USD | E60: 0.0565 | F60: 45566 | G60: 46681 | H60: 750000 | I60: 219651.98 | L60: =SUM(I60:K60) -> 219651.98 | M60: =(G60-$M$2) -> 781 | N60: =VLOOKUP(M60,T!$A$12:$C$19,3,TRUE) -> 1-3 Years | P60: =IF(P$1=$N60,$L60,0) -> 0 | Q60: =IF(Q$1=$N60,$L60,0) -> 0 | R60: =IF(R$1=$N60,$L60,0) -> 0 | S60: =IF(S$1=$N60,$L60,0) -> 0 | T60: =IF(T$1=$N60,$L60,0) -> 0 | U60: =IF(U$1=$N60,$L60,0) -> 219651.98 | V60: =IF(V$1=$N60,$L60,0) -> 0 | W60: =IF(W$1=$N60,$L60,0) -> 0 | X60: =SUM(P60:W60) -> 219651.98
A61: Nations Trust Bank | B61: PI20241129-126 | C61: USD | E61: 0.0565 | F61: 45566 | G61: 46681 | H61: 1470000 | I61: 430517.87 | L61: =SUM(I61:K61) -> 430517.87 | M61: =(G61-$M$2) -> 781 | N61: =VLOOKUP(M61,T!$A$12:$C$19,3,TRUE) -> 1-3 Years | P61: =IF(P$1=$N61,$L61,0) -> 0 | Q61: =IF(Q$1=$N61,$L61,0) -> 0 | R61: =IF(R$1=$N61,$L61,0) -> 0 | S61: =IF(S$1=$N61,$L61,0) -> 0 | T61: =IF(T$1=$N61,$L61,0) -> 0 | U61: =IF(U$1=$N61,$L61,0) -> 430517.87 | V61: =IF(V$1=$N61,$L61,0) -> 0 | W61: =IF(W$1=$N61,$L61,0) -> 0 | X61: =SUM(P61:W61) -> 430517.87
T62: =IF((W62+V62+U62)>0,0,IF(M62<=1,L62,0)) -> 0 | U62: =IF((W62+V62)>0,0,IF(M62>1,L62,0)) -> 0 | V62: =IF(W62>0,0,IF(M62>3,L62,0)) -> 0 | W62: =IF(M62>5,L62,0) -> 0 | X62: =SUM(P62:W62) -> 0
X63: =SUM(P63:W63) -> 0
I64: =SUM(I59:I63) -> 869821.82 | L64: =SUM(L59:L63) -> 869821.82 | T64: =SUM(T59:T63) -> 0 | U64: =SUM(U59:U63) -> 869821.82 | V64: =SUM(V59:V63) -> 0 | W64: =SUM(W59:W63) -> 0 | X64: =SUM(X59:X63) -> 869821.82
A65: Interest receivable | L65: 1498.2949 | T65: =T64/$X$64*$L$65 -> 0 | U65: =U64/$X$64*$L$65 -> 1498.2949 | V65: =V64/$X$64*$L$65 -> 0 | W65: =W64/$X$64*$L$65 -> 0 | X65: =SUM(P65:W65) -> 1498.2949
A66: Exchange Gain or Loss | L66: 28503.693 | U66: =U64/$X$64*$L$66 -> 28503.693 | V66: =V64/$X$64*$L$66 -> 0 | W66: =W64/$X$64*$L$66 -> 0 | X66: =SUM(P66:W66) -> 28503.693
A67: Provision for Impairment on FD | L67: -164.87356 | T67: =T64/$X$64*$L$67 -> 0 | U67: =U64/$X$64*$L$67 -> -164.87356 | V67: =V64/$X$64*$L$67 -> 0 | W67: =W64/$X$64*$L$67 -> 0 | X67: =SUM(P67:W67) -> -164.87356
I68: =SUM(I64:I67) -> 869821.82 | L68: =SUM(L64:L67) -> 899658.94 | P68: =SUM(P64:P67) -> 0 | Q68: =SUM(Q64:Q67) -> 0 | R68: =SUM(R64:R67) -> 0 | S68: =SUM(S64:S67) -> 0 | T68: =SUM(T64:T67) -> 0 | U68: =SUM(U64:U67) -> 899658.94 | V68: =SUM(V64:V67) -> 0 | W68: =SUM(W64:W67) -> 0 | X68: =SUM(X64:X67) -> 899658.94 | Y68: =X68-L68 -> 0
A70: Repos & Treasury Bills
A71: Institution | B71: Reference Number | C71: Instrument | E71: Rate | F71: Date of Investment | G71: Date of Maturity | H71: Tenor | I71: Value in LKR (000) | J71: Interest Receivable | L71: Total | M71: Months
A72: DFCC Bank PLC | B72: RF20250516-004 | C72: LKB00428B156 | E72: 0.081 | F72: 45786 | G72: 45909 | H72: 123 (days) | I72: 500000 | L72: =SUM(I72:K72) -> 500000 | M72: =(G72-$M$2) -> 9 | N72: =VLOOKUP(M72,T!$A$12:$C$19,3,TRUE) -> 7-30 Days | P72: =IF(P$1=$N72,$L72,0) -> 0 | Q72: =IF(Q$1=$N72,$L72,0) -> 500000 | R72: =IF(R$1=$N72,$L72,0) -> 0 | S72: =IF(S$1=$N72,$L72,0) -> 0 | T72: =IF(T$1=$N72,$L72,0) -> 0 | U72: =IF(U$1=$N72,$L72,0) -> 0 | V72: =IF(V$1=$N72,$L72,0) -> 0 | W72: =IF(W$1=$N72,$L72,0) -> 0 | X72: =SUM(P72:W72) -> 500000
A73: DFCC Bank PLC | B73: RF20250516-003 | C73: LKB00428B156 | E73: 0.081 | F73: 45786 | G73: 45909 | H73: 123 (days) | I73: 500000 | L73: =SUM(I73:K73) -> 500000 | M73: =(G73-$M$2) -> 9 | N73: =VLOOKUP(M73,T!$A$12:$C$19,3,TRUE) -> 7-30 Days | P73: =IF(P$1=$N73,$L73,0) -> 0 | Q73: =IF(Q$1=$N73,$L73,0) -> 500000 | R73: =IF(R$1=$N73,$L73,0) -> 0 | S73: =IF(S$1=$N73,$L73,0) -> 0 | T73: =IF(T$1=$N73,$L73,0) -> 0 | U73: =IF(U$1=$N73,$L73,0) -> 0 | V73: =IF(V$1=$N73,$L73,0) -> 0 | W73: =IF(W$1=$N73,$L73,0) -> 0 | X73: =SUM(P73:W73) -> 500000
A74: Interest receivable | F74: 45786 | G74: 45909 | J74: 25520.548 | L74: =SUM(I74:K74) -> 25520.548 | M74: =(G74-$M$2) -> 9 | N74: =VLOOKUP(M74,T!$A$12:$C$19,3,TRUE) -> 7-30 Days | P74: =IF(P$1=$N74,$L74,0) -> 0 | Q74: =IF(Q$1=$N74,$L74,0) -> 25520.548 | R74: =IF(R$1=$N74,$L74,0) -> 0 | S74: =IF(S$1=$N74,$L74,0) -> 0 | T74: =IF(T$1=$N74,$L74,0) -> 0 | U74: =IF(U$1=$N74,$L74,0) -> 0 | V74: =IF(V$1=$N74,$L74,0) -> 0 | W74: =IF(W$1=$N74,$L74,0) -> 0 | X74: =SUM(P74:W74) -> 25520.548
X77: =SUM(P77:W77) -> 0
H78: =SUM(H71:H77) -> 0 | L78: =SUM(L71:L77) -> 1025520.5 | P78: =SUM(P71:P77) -> 0 | Q78: =SUM(Q71:Q77) -> 1025520.5 | R78: =SUM(R71:R77) -> 0 | S78: =SUM(S71:S77) -> 0 | T78: =SUM(T71:T77) -> 0 | U78: =SUM(U71:U77) -> 0 | V78: =SUM(V71:V77) -> 0 | W78: =SUM(W71:W77) -> 0 | X78: =SUM(X71:X77) -> 1025520.5 | Y78: =X78-L78 -> 0
L80: Treasury Bonds | P80: =P54 -> 0 | Q80: =Q54 -> 0 | R80: =R54 -> 0 | S80: =S54 -> 0 | T80: =T54 -> 1558322.6 | U80: =U54 -> 3688478.7 | V80: =V54 -> 351444.68 | W80: =W54 -> 491620.68 | X80: =X54 -> 6089866.7
L81: FD & Bank Balances | P81: =P68 -> 0 | Q81: =Q68 -> 0 | R81: =R68 -> 0 | S81: =S68 -> 0 | T81: =T68 -> 0 | U81: =U68 -> 899658.94 | V81: =V68 -> 0 | W81: =W68 -> 0 | X81: =X68 -> 899658.94
...

Sheet Other Assets
A1: IFRS Code | B1: GL Code | C1: Account Name | D1: Balance | F1: Less than 7 Days (b) | G1: 7-30 Days (c) | H1: 1-3 Months (d) | I1: 3-6 Months (e) | J1: 6-12 Months (f) | K1: 1-3 Years (g) | L1: 3-5 Years (h) | M1: Over 5 Years (i) | N1: Unclassified (j) | O1: Total (i) | P1: Diff
A2: BS-1.1.18.0.0.0 | B2: 0185 | C2: REPOSSESSED ASSETS - LEASING | D2: =_xlfn.IFNA(IF(VLOOKUP(B2,'System TB'!$A:$C,3,FALSE)>0,VLOOKUP(B2,'System TB'!$A:$C,3,FALSE),0),0) -> 27110584 | H2: =D2 -> 27110584 | O2: =SUM(F2:N2) -> 27110584 | P2: =O2-D2 -> 0
A3: BS-1.1.18.0.0.0 | B3: 0186 | C3: REPOSSESSED ASSETS - HIRE PURCHASE | D3: =_xlfn.IFNA(IF(VLOOKUP(B3,'System TB'!$A:$C,3,FALSE)>0,VLOOKUP(B3,'System TB'!$A:$C,3,FALSE),0),0) -> 0 | H3: =D3 -> 0 | O3: =SUM(F3:N3) -> 0 | P3: =O3-D3 -> 0
A4: BS-1.1.18.0.0.0 | B4: 1248 | C4: THREE WHEELER STOCK | D4: =_xlfn.IFNA(IF(VLOOKUP(B4,'System TB'!$A:$C,3,FALSE)>0,VLOOKUP(B4,'System TB'!$A:$C,3,FALSE),0),0) -> 0 | H4: =D4 -> 0 | O4: =SUM(F4:N4) -> 0 | P4: =O4-D4 -> 0
A5: BS-1.1.18.0.0.0 | B5: 0153 | C5: CURRENT ACCOUNT - AMPARA | D5: =_xlfn.IFNA(IF(VLOOKUP(B5,'System TB'!$A:$C,3,FALSE)>0,VLOOKUP(B5,'System TB'!$A:$C,3,FALSE),0),0) -> 0 | F5: =D5 -> 0 | O5: =SUM(F5:N5) -> 0 | P5: =O5-D5 -> 0
A6: BS-1.1.18.0.0.0 | B6: 0154 | C6: CURRENT ACCOUNT - ANURADHAPURA | D6: =_xlfn.IFNA(IF(VLOOKUP(B6,'System TB'!$A:$C,3,FALSE)>0,VLOOKUP(B6,'System TB'!$A:$C,3,FALSE),0),0) -> 0 | F6: =D6 -> 0 | O6: =SUM(F6:N6) -> 0 | P6: =O6-D6 -> 0
A7: BS-1.1.18.0.0.0 | B7: 0155 | C7: CURRENT ACCOUNT - BADULLA | D7: =_xlfn.IFNA(IF(VLOOKUP(B7,'System TB'!$A:$C,3,FALSE)>0,VLOOKUP(B7,'System TB'!$A:$C,3,FALSE),0),0) -> 0 | F7: =D7 -> 0 | O7: =SUM(F7:N7) -> 0 | P7: =O7-D7 -> 0
A8: BS-1.1.18.0.0.0 | B8: 0156 | C8: CURRENT ACCOUNT - CHILAW | D8: =_xlfn.IFNA(IF(VLOOKUP(B8,'System TB'!$A:$C,3,FALSE)>0,VLOOKUP(B8,'System TB'!$A:$C,3,FALSE),0),0) -> 0 | F8: =D8 -> 0 | O8: =SUM(F8:N8) -> 0 | P8: =O8-D8 -> 0
A9: BS-1.1.18.0.0.0 | B9: 0157 | C9: CURRENT ACCOUNT - DAMBULLA | D9: =_xlfn.IFNA(IF(VLOOKUP(B9,'System TB'!$A:$C,3,FALSE)>0,VLOOKUP(B9,'System TB'!$A:$C,3,FALSE),0),0) -> 0 | F9: =D9 -> 0 | O9: =SUM(F9:N9) -> 0 | P9: =O9-D9 -> 0
A10: BS-1.1.18.0.0.0 | B10: 0158 | C10: CURRENT ACCOUNT - DEHIATTAKANDIYA | D10: =_xlfn.IFNA(IF(VLOOKUP(B10,'System TB'!$A:$C,3,FALSE)>0,VLOOKUP(B10,'System TB'!$A:$C,3,FALSE),0),0) -> 0 | F10: =D10 -> 0 | O10: =SUM(F10:N10) -> 0 | P10: =O10-D10 -> 0
A11: BS-1.1.18.0.0.0 | B11: 0159 | C11: CURRENT ACCOUNT - EMBILIPITIYA | D11: =_xlfn.IFNA(IF(VLOOKUP(B11,'System TB'!$A:$C,3,FALSE)>0,VLOOKUP(B11,'System TB'!$A:$C,3,FALSE),0),0) -> 0 | F11: =D11 -> 0 | O11: =SUM(F11:N11) -> 0 | P11: =O11-D11 -> 0
A12: BS-1.1.18.0.0.0 | B12: 0160 | C12: CURRENT ACCOUNT - GALLE | D12: =_xlfn.IFNA(IF(VLOOKUP(B12,'System TB'!$A:$C,3,FALSE)>0,VLOOKUP(B12,'System TB'!$A:$C,3,FALSE),0),0) -> 0 | F12: =D12 -> 0 | O12: =SUM(F12:N12) -> 0 | P12: =O12-D12 -> 0
A13: BS-1.1.18.0.0.0 | B13: 0161 | C13: CURRENT ACCOUNT - HEAD OFFICE | D13: =_xlfn.IFNA(IF(VLOOKUP(B13,'System TB'!$A:$C,3,FALSE)>0,VLOOKUP(B13,'System TB'!$A:$C,3,FALSE),0),0) -> 0 | F13: =D13 -> 0 | O13: =SUM(F13:N13) -> 0 | P13: =O13-D13 -> 0
A14: BS-1.1.18.0.0.0 | B14: 0162 | C14: CURRENT ACCOUNT - KANDY | D14: =_xlfn.IFNA(IF(VLOOKUP(B14,'System TB'!$A:$C,3,FALSE)>0,VLOOKUP(B14,'System TB'!$A:$C,3,FALSE),0),0) -> 0 | F14: =D14 -> 0 | O14: =SUM(F14:N14) -> 0 | P14: =O14-D14 -> 0
A15: BS-1.1.18.0.0.0 | B15: 0163 | C15: CURRENT ACCOUNT - KURUNEGALA | D15: =_xlfn.IFNA(IF(VLOOKUP(B15,'System TB'!$A:$C,3,FALSE)>0,VLOOKUP(B15,'System TB'!$A:$C,3,FALSE),0),0) -> 0 | F15: =D15 -> 0 | O15: =SUM(F15:N15) -> 0 | P15: =O15-D15 -> 0
A16: BS-1.1.18.0.0.0 | B16: 0164 | C16: CURRENT ACCOUNT - MADAPATHA | D16: =_xlfn.IFNA(IF(VLOOKUP(B16,'System TB'!$A:$C,3,FALSE)>0,VLOOKUP(B16,'System TB'!$A:$C,3,FALSE),0),0) -> 0 | F16: =D16 -> 0 | O16: =SUM(F16:N16) -> 0 | P16: =O16-D16 -> 0
... A26: BS-1.1.18.0.0.0 | B26: 0174 | C26: CURRENT ACCOUNT - YAKKALA | D26: =_xlfn.IFNA(IF(VLOOKUP(B26,'System TB'!$A:$C,3,FALSE)>0,VLOOKUP(B26,'System TB'!$A:$C,3,FALSE),0),0) -> 0 | F26: =D26 -> 0 | O26: =SUM(F26:N26) -> 0 | P26: =O26-D26 -> 0
A27: BS-1.1.18.0.0.0 | B27: 0187 | C27: ADVERTISING CHARGES RECOVARABLE | D27: =_xlfn.IFNA(IF(VLOOKUP(B27,'System TB'!$A:$C,3,FALSE)>0,VLOOKUP(B27,'System TB'!$A:$C,3,FALSE),0),0) -> 20640850 | G27: =D27 -> 20640850 | O27: =SUM(F27:N27) -> 20640850 | P27: =O27-D27 -> 0
A28: BS-1.1.18.0.0.0 | B28: 0198 | C28: RENT DEPOSITS | D28: =_xlfn.IFNA(IF(VLOOKUP(B28,'System TB'!$A:$C,3,FALSE)>0,VLOOKUP(B28,'System TB'!$A:$C,3,FALSE),0),0) -> 6488000 | L28: =D28 -> 6488000 | O28: =SUM(F28:N28) -> 6488000 | P28: =O28-D28 -> 0
A29: BS-1.1.18.0.0.0 | B29: 0200 | C29: REFUNDABLE SECURITY DEPOSITS | D29: =_xlfn.IFNA(IF(VLOOKUP(B29,'System TB'!$A:$C,3,FALSE)>0,VLOOKUP(B29,'System TB'!$A:$C,3,FALSE),0),0) -> 21760102 | L29: =D29 -> 21760102 | O29: =SUM(F29:N29) -> 21760102 | P29: =O29-D29 -> 0
A30: BS-1.1.18.0.0.0 | B30: 0201 | C30: S.S.P. CORPORATE SERVICES LTD. | D30: =_xlfn.IFNA(IF(VLOOKUP(B30,'System TB'!$A:$C,3,FALSE)>0,VLOOKUP(B30,'System TB'!$A:$C,3,FALSE),0),0) -> 0 | G30: =D30 -> 0 | O30: =SUM(F30:N30) -> 0 | P30: =O30-D30 -> 0
A31: BS-1.1.18.0.0.0 | B31: 0202 | C31: STAFF LOANS AND ADVANCES | D31: =_xlfn.IFNA(IF(VLOOKUP(B31,'System TB'!$A:$C,3,FALSE)>0,VLOOKUP(B31,'System TB'!$A:$C,3,FALSE),0),0) -> 9263191.3 | G31: =D31/6 -> 1543865.2 | H31: =G31*2 -> 3087730.4 | I31: =G31*3 -> 4631595.6 | O31: =SUM(F31:N31) -> 9263191.3 | P31: =O31-D31 -> 0
A32: BS-1.1.17.0.0.0 | B32: 0269 | C32: DP INSURANCE BROKERS LIMITED | D32: =_xlfn.IFNA(IF(VLOOKUP(B32,'System TB'!$A:$C,3,FALSE)>0,VLOOKUP(B32,'System TB'!$A:$C,3,FALSE),0),0) -> 55000 | G32: =D32 -> 55000 | O32: =SUM(F32:N32) -> 55000 | P32: =O32-D32 -> 0
A33: BS-1.1.17.0.0.0 | B33: 0283 | C33: DP GLOBAL SECURITIES (PVT) lTD | D33: =_xlfn.IFNA(IF(VLOOKUP(B33,'System TB'!$A:$C,3,FALSE)>0,VLOOKUP(B33,'System TB'!$A:$C,3,FALSE),0),0) -> 0 | G33: =D33 -> 0 | O33: =SUM(F33:N33) -> 0 | P33: =O33-D33 -> 0
A34: BS-1.1.18.0.0.0 | B34: 0394 | C34: ADVANCES | D34: =_xlfn.IFNA(IF(VLOOKUP(B34,'System TB'!$A:$C,3,FALSE)>0,VLOOKUP(B34,'System TB'!$A:$C,3,FALSE),0),0) -> 72000881 | H34: =D34 -> 72000881 | O34: =SUM(F34:N34) -> 72000881 | P34: =O34-D34 -> 0
A35: BS-1.1.18.0.0.0 | B35: 0431 | C35: CURRENT ACCOUNT - KALUTHARA | D35: =_xlfn.IFNA(IF(VLOOKUP(B35,'System TB'!$A:$C,3,FALSE)>0,VLOOKUP(B35,'System TB'!$A:$C,3,FALSE),0),0) -> 0 | F35: =D35 -> 0 | O35: =SUM(F35:N35) -> 0 | P35: =O35-D35 -> 0
A36: BS-1.1.18.0.0.0 | B36: 0435 | C36: CURRENT ACCOUNT - AMBALANTHOTA | D36: =_xlfn.IFNA(IF(VLOOKUP(B36,'System TB'!$A:$C,3,FALSE)>0,VLOOKUP(B36,'System TB'!$A:$C,3,FALSE),0),0) -> 0 | F36: =D36 -> 0 | O36: =SUM(F36:N36) -> 0 | P36: =O36-D36 -> 0
A37: BS-1.1.18.0.0.0 | B37: 0457 | C37: CURRENT ACCOUNT - BATTARAMULLA | D37: =_xlfn.IFNA(IF(VLOOKUP(B37,'System TB'!$A:$C,3,FALSE)>0,VLOOKUP(B37,'System TB'!$A:$C,3,FALSE),0),0) -> 0 | F37: =D37 -> 0 | O37: =SUM(F37:N37) -> 0 | P37: =O37-D37 -> 0
A38: BS-1.1.18.0.0.0 | B38: 0952 | C38: OTHER RECEIVABLE CONTRA A/C | D38: =_xlfn.IFNA(IF(VLOOKUP(B38,'System TB'!$A:$C,3,FALSE)>0,VLOOKUP(B38,'System TB'!$A:$C,3,FALSE),0),0) -> 1159682.7 | H38: =D38 -> 1159682.7 | O38: =SUM(F38:N38) -> 1159682.7 | P38: =O38-D38 -> 0
A39: BS-1.1.18.0.0.0 | B39: 0953 | C39: REFUNDS ON CANCELLED INSURANCE POLICIES | D39: =_xlfn.IFNA(IF(VLOOKUP(B39,'System TB'!$A:$C,3,FALSE)>0,VLOOKUP(B39,'System TB'!$A:$C,3,FALSE),0),0) -> 0 | G39: =D39 -> 0 | O39: =SUM(F39:N39) -> 0 | P39: =O39-D39 -> 0
A40: BS-1.1.18.0.0.0 | B40: 0954 | C40: PARKING CHARGES RECOVERABLE | D40: =_xlfn.IFNA(IF(VLOOKUP(B40,'System TB'!$A:$C,3,FALSE)>0,VLOOKUP(B40,'System TB'!$A:$C,3,FALSE),0),0) -> 0 | G40: =D40 -> 0 | O40: =SUM(F40:N40) -> 0 | P40: =O40-D40 -> 0
A41: BS-1.1.18.0.0.0 | B41: 1151 | C41: TELEPHONE OVERCHARGES RECOVERABLE | D41: =_xlfn.IFNA(IF(VLOOKUP(B41,'System TB'!$A:$C,3,FALSE)>0,VLOOKUP(B41,'System TB'!$A:$C,3,FALSE),0),0) -> 0 | G41: =D41 -> 0 | O41: =SUM(F41:N41) -> 0 | P41: =O41-D41 -> 0
A42: BS-1.1.18.0.0.0 | B42: 1153 | C42: CURRENT ACCOUNT - BATTICALOA | D42: =_xlfn.IFNA(IF(VLOOKUP(B42,'System TB'!$A:$C,3,FALSE)>0,VLOOKUP(B42,'System TB'!$A:$C,3,FALSE),0),0) -> 0 | F42: =D42 -> 0 | O42: =SUM(F42:N42) -> 0 | P42: =O42-D42 -> 0
A43: BS-1.1.18.0.0.0 | B43: 1171 | C43: RECEIPT CONFIRMATION SUSPENSE | D43: =_xlfn.IFNA(IF(VLOOKUP(B43,'System TB'!$A:$C,3,FALSE)>0,VLOOKUP(B43,'System TB'!$A:$C,3,FALSE),0),0) -> 1229510 | H43: =D43 -> 1229510 | O43: =SUM(F43:N43) -> 1229510 | P43: =O43-D43 -> 0
A44: BS-1.1.18.0.0.0 | B44: 1197 | C44: ADVANCE PAYMENT OF BULK PURCHASE-3W | D44: =_xlfn.IFNA(IF(VLOOKUP(B44,'System TB'!$A:$C,3,FALSE)>0,VLOOKUP(B44,'System TB'!$A:$C,3,FALSE),0),0) -> 5000000 | G44: =D44 -> 5000000 | O44: =SUM(F44:N44) -> 5000000 | P44: =O44-D44 -> 0
A45: BS-1.1.17.0.0.0 | B45: 1212 | C45: DP GLOBAL VENTURES (PVT) LTD | D45: =_xlfn.IFNA(IF(VLOOKUP(B45,'System TB'!$A:$C,3,FALSE)>0,VLOOKUP(B45,'System TB'!$A:$C,3,FALSE),0),0) -> 0.04 | G45: =D45 -> 0.04 | O45: =SUM(F45:N45) -> 0.04 | P45: =O45-D45 -> 0
A46: BS-1.1.18.0.0.0 | B46: 1218 | C46: CURRENT ACCOUNT - PILIYANDALA | D46: =_xlfn.IFNA(IF(VLOOKUP(B46,'System TB'!$A:$C,3,FALSE)>0,VLOOKUP(B46,'System TB'!$A:$C,3,FALSE),0),0) -> 0 | F46: =D46 -> 0 | O46: =SUM(F46:N46) -> 0 | P46: =O46-D46 -> 0
A47: BS-1.1.18.0.0.0 | B47: 1219 | C47: CURRENT ACCOUNT - TRINCOMALEE | D47: =_xlfn.IFNA(IF(VLOOKUP(B47,'System TB'!$A:$C,3,FALSE)>0,VLOOKUP(B47,'System TB'!$A:$C,3,FALSE),0),0) -> 0 | F47: =D47 -> 0 | O47: =SUM(F47:N47) -> 0 | P47: =O47-D47 -> 0
A48: BS-1.1.18.0.0.0 | B48: 1259 | C48: CURRENT ACCOUNT - VAUNIYA | D48: =_xlfn.IFNA(IF(VLOOKUP(B48,'System TB'!$A:$C,3,FALSE)>0,VLOOKUP(B48,'System TB'!$A:$C,3,FALSE),0),0) -> 0 | F48: =D48 -> 0 | O48: =SUM(F48:N48) -> 0 | P48: =O48-D48 -> 0
A49: BS-1.1.18.0.0.0 | B49: 1262 | C49: CURRENT ACCOUNT - KEGALLE | D49: =_xlfn.IFNA(IF(VLOOKUP(B49,'System TB'!$A:$C,3,FALSE)>0,VLOOKUP(B49,'System TB'!$A:$C,3,FALSE),0),0) -> 0 | F49: =D49 -> 0 | O49: =SUM(F49:N49) -> 0 | P49: =O49-D49 -> 0
...

Sheet Borrowings
C1: =SUM(C3:C1048576) -> 3.4569024e+10 | F1: ='NBD-MF-01-SOFP'!D2 -> 45900
A2: Source of Facility | B2: Type of Rate | C2: Amount | D2: Rate | E2: Maturity Date | F2: Residual Period | G2: Bucket | I2: Row Labels | J2: Sum of Amount | L2: Row Labels | M2: Sum of Amount
A3: BOC | B3: STL | C3: 250000000 | D3: 0.075 | E3: 45904 | F3: =E3-$F$1 -> 4 | G3: =VLOOKUP(F3,T!$A$2:$C$9,3,TRUE) -> 1. Less than 7 Days | I3: 1. Less than 7 Days | J3: 250000000 | L3: 1. Less than 7 Days | M3: 250000000 | N3: =ROUND((M3+M14)/1000,0) -> 3063383
A4: HNB | B4: STL | C4: 500000000 | D4: 0.077 | E4: 45909 | F4: =E4-$F$1 -> 9 | G4: =VLOOKUP(F4,T!$A$2:$C$9,3,TRUE) -> 2. 7-30 Days | I4: 2. 7-30 Days | J4: 7.8980623e+09 | L4: 2. 7-30 Days | M4: 7.8980623e+09 | N4: =ROUND(M4/1000,0) -> 7898062
A5: HNB | B5: STL | C5: 500000000 | D5: 0.077 | E5: 45909 | F5: =E5-$F$1 -> 9 | G5: =VLOOKUP(F5,T!$A$2:$C$9,3,TRUE) -> 2. 7-30 Days | I5: 3. 1-3 Months | J5: 3.2971519e+09 | L5: 3. 1-3 Months | M5: 3.2971519e+09 | N5: =ROUND(M5/1000,0) -> 3297152
A6: Sampath | B6: STL | C6: 500000000 | D6: 0.0747 | E6: 45912 | F6: =E6-$F$1 -> 12 | G6: =VLOOKUP(F6,T!$A$2:$C$9,3,TRUE) -> 2. 7-30 Days | I6: 4. 3-6 Months | J6: 1.5489507e+09 | L6: 4. 3-6 Months | M6: 1.5489507e+09 | N6: =ROUND(M6/1000,0) -> 1548951
A7: Seylan | B7: STL | C7: 500000000 | D7: 0.077 | E7: 45912 | F7: =E7-$F$1 -> 12 | G7: =VLOOKUP(F7,T!$A$2:$C$9,3,TRUE) -> 2. 7-30 Days | I7: 5. 6-12 Months | J7: 3.3023263e+09 | L7: 5. 6-12 Months | M7: 3.3023263e+09 | N7: =ROUND(M7/1000,0) -> 3302326
A8: Seylan LT 3 | B8: LTL | C8: 50000000 | D8: 0.12 | E8: 45913 | F8: =E8-$F$1 -> 13 | G8: =VLOOKUP(F8,T!$A$2:$C$9,3,TRUE) -> 2. 7-30 Days | I8: 6. 1-3 Years | J8: 1.2837779e+10 | L8: 6. 1-3 Years | M8: 1.2837779e+10 | N8: =ROUND(M8/1000,0) -> 12837779
A9: Seylan LT 3 | B9: LTL | C9: 25000000 | D9: 0.12 | E9: 45914 | F9: =E9-$F$1 -> 14 | G9: =VLOOKUP(F9,T!$A$2:$C$9,3,TRUE) -> 2. 7-30 Days | I9: 7. 3-5 Years | J9: 2.7324978e+09 | L9: 7. 3-5 Years | M9: 2.7324978e+09 | N9: =ROUND(M9/1000,0) -> 2732498
A10: DFCC LT | B10: LTL | C10: 12500000 | D10: 0.0925 | E10: 45915 | F10: =E10-$F$1 -> 15 | G10: =VLOOKUP(F10,T!$A$2:$C$9,3,TRUE) -> 2. 7-30 Days | I10: Grand Total | J10: 3.1866768e+10 | L10: 8. Over 5 Years | M10: 0 | N10: =ROUND(M10/1000,0) -> 0
A11: DFCC LT | B11: LTL | C11: 12500000 | D11: 0.0925 | E11: 45915 | F11: =E11-$F$1 -> 15 | G11: =VLOOKUP(F11,T!$A$2:$C$9,3,TRUE) -> 2. 7-30 Days | L11: Grand Total | M11: =SUM(M3:M10) -> 3.1866768e+10 | N11: =SUM(N3:N10) -> 34680151
A12: DFCC LT | B12: LTL | C12: 8333334 | D12: 0.0925 | E12: 45915 | F12: =E12-$F$1 -> 15 | G12: =VLOOKUP(F12,T!$A$2:$C$9,3,TRUE) -> 2. 7-30 Days | M12: =M21 -> 3.4680151e+10
A13: HNB | B13: STL | C13: 500000000 | D13: 0.077 | E13: 45915 | F13: =E13-$F$1 -> 15 | G13: =VLOOKUP(F13,T!$A$2:$C$9,3,TRUE) -> 2. 7-30 Days | M13: =M12-M11 -> 2.8133833e+09
A14: NTB LT 3 | B14: LTL | C14: 16666667 | D14: 0.0802 | E14: 45915 | F14: =E14-$F$1 -> 15 | G14: =VLOOKUP(F14,T!$A$2:$C$9,3,TRUE) -> 2. 7-30 Days | L14: Diff here | M14: 2.8133833e+09
A15: Seylan LT | B15: LTL | C15: 25000000 | D15: 0.085 | E15: 45915 | F15: =E15-$F$1 -> 15 | G15: =VLOOKUP(F15,T!$A$2:$C$9,3,TRUE) -> 2. 7-30 Days
A16: Commercial Bank | B16: STL | C16: 300000000 | D16: 0.075 | E16: 45918 | F16: =E16-$F$1 -> 18 | G16: =VLOOKUP(F16,T!$A$2:$C$9,3,TRUE) -> 2. 7-30 Days | L16: Forign Funding | M16: =+'NBD-MF-01-SOFP'!E125 -> 9.4477295e+08
A17: NTB LT 2 | B17: LTL | C17: 25000000 | D17: 0.0802 | E17: 45918 | F17: =E17-$F$1 -> 18 | G17: =VLOOKUP(F17,T!$A$2:$C$9,3,TRUE) -> 2. 7-30 Days | L17: RPT Loan - Capital | M17: 0
A18: Seylan | B18: STL | C18: 200000000 | D18: 0.075 | E18: 45918 | F18: =E18-$F$1 -> 18 | G18: =VLOOKUP(F18,T!$A$2:$C$9,3,TRUE) -> 2. 7-30 Days | L18: RPT Loan - Interest | M18: 0
A19: Seylan | B19: STL | C19: 200000000 | D19: 0.075 | E19: 45918 | F19: =E19-$F$1 -> 18 | G19: =VLOOKUP(F19,T!$A$2:$C$9,3,TRUE) -> 2. 7-30 Days | L19: Total RPT | M19: =SUM(M17:M18) -> 0
A20: Seylan | B20: STL | C20: 500000000 | D20: 0.075 | E20: 45918 | F20: =E20-$F$1 -> 18 | G20: =VLOOKUP(F20,T!$A$2:$C$9,3,TRUE) -> 2. 7-30 Days | L20: Bank Borrowings | M20: ='NBD-MF-01-SOFP'!E94+'NBD-MF-01-SOFP'!E95 -> 3.3735379e+10
A21: Cargills LT | B21: LTL | C21: 13775273 | D21: 0.12 | E21: 45919 | F21: =E21-$F$1 -> 19 | G21: =VLOOKUP(F21,T!$A$2:$C$9,3,TRUE) -> 2. 7-30 Days | M21: =M19+M20+M16 -> 3.4680151e+10 | N21: =ROUND(M21/1000,0) -> 34680151
A22: Commercial Bank | B22: STL | C22: 400000000 | D22: 0.075 | E22: 45919 | F22: =E22-$F$1 -> 19 | G22: =VLOOKUP(F22,T!$A$2:$C$9,3,TRUE) -> 2. 7-30 Days
A23: NDB | B23: STL | C23: 500000000 | D23: 0.075 | E23: 45919 | F23: =E23-$F$1 -> 19 | G23: =VLOOKUP(F23,T!$A$2:$C$9,3,TRUE) -> 2. 7-30 Days
A24: Sampath | B24: STL | C24: 400000000 | D24: 0.0747 | E24: 45919 | F24: =E24-$F$1 -> 19 | G24: =VLOOKUP(F24,T!$A$2:$C$9,3,TRUE) -> 2. 7-30 Days
A25: Sampath | B25: STL | C25: 550000000 | D25: 0.0747 | E25: 45919 | F25: =E25-$F$1 -> 19 | G25: =VLOOKUP(F25,T!$A$2:$C$9,3,TRUE) -> 2. 7-30 Days
A26: Seylan | B26: STL | C26: 500000000 | D26: 0.075 | E26: 45919 | F26: =E26-$F$1 -> 19 | G26: =VLOOKUP(F26,T!$A$2:$C$9,3,TRUE) -> 2. 7-30 Days
A27: Seylan LT | B27: LTL | C27: 25000000 | D27: 0.085 | E27: 45921 | F27: =E27-$F$1 -> 21 | G27: =VLOOKUP(F27,T!$A$2:$C$9,3,TRUE) -> 2. 7-30 Days
A28: Commercial Bank LT 3 | B28: LTL | C28: 20800000 | D28: 0.1075 | E28: 45922 | F28: =E28-$F$1 -> 22 | G28: =VLOOKUP(F28,T!$A$2:$C$9,3,TRUE) -> 2. 7-30 Days
A29: Commercial Bank LT 3 | B29: LTL | C29: 20800000 | D29: 0.1075 | E29: 45924 | F29: =E29-$F$1 -> 24 | G29: =VLOOKUP(F29,T!$A$2:$C$9,3,TRUE) -> 2. 7-30 Days
A30: Commercial Bank LT 2 | B30: LTL | C30: 16650000 | D30: 0.09 | E30: 45925 | F30: =E30-$F$1 -> 25 | G30: =VLOOKUP(F30,T!$A$2:$C$9,3,TRUE) -> 2. 7-30 Days
A31: Commercial Bank LT 2 | B31: LTL | C31: 16650000 | D31: 0.09 | E31: 45926 | F31: =E31-$F$1 -> 26 | G31: =VLOOKUP(F31,T!$A$2:$C$9,3,TRUE) -> 2. 7-30 Days
A32: Commercial Bank | B32: STL | C32: 200000000 | D32: 0.076 | E32: 45926 | F32: =E32-$F$1 -> 26 | G32: =VLOOKUP(F32,T!$A$2:$C$9,3,TRUE) -> 2. 7-30 Days
A33: Commercial Bank | B33: STL | C33: 200000000 | D33: 0.076 | E33: 45926 | F33: =E33-$F$1 -> 26 | G33: =VLOOKUP(F33,T!$A$2:$C$9,3,TRUE) -> 2. 7-30 Days
... A1146: NTB LT 3 | B1146: LTL | C1146: 16666666 | D1146: 0.0802 | E1146: 47724 | F1146: =E1146-$F$1 -> 1824 | G1146: =VLOOKUP(F1146,T!$A$2:$C$9,3,TRUE) -> 7. 3-5 Years

Sheet Portfolio
K1: 1000
C2: Less than 7 Days (b) | D2: 7-30 Days (c) | E2: 1-3 Months (d) | F2: 3-6 Months (e) | G2: 6-12 Months (f) | H2: 1-3 Years (g) | I2: 3-5 Years (h) | J2: Over 5 Years (i) | K2: Total | N2: Gross | O2: Rec | P2: Diff
A3: Future Capital
B4: NP Total | C4: 0 | D4: 64590 | E4: 1.1915279e+08 | F4: 169451449 | G4: 3.1439082e+08 | H4: 677258756 | I4: 87706233 | J4: 0 | K4: =SUM(C4:J4) -> 1.3680246e+09 | M4: Margin Trading | N4: =O4 -> 3.0599423e+09 | O4: 3.0599423e+09 | P4: =N4-O4 -> 0
B5: LE - NP | C5: 0 | D5: 64590 | E5: 107439032 | F5: 159722533 | G5: 294052496 | H5: 631507681 | I5: 71555208 | J5: 0 | K5: =SUM(C5:J5) -> 1264341540 | M5: Lease & Loan | N5: =K10+N20+P20+O20+Q20 -> 5.6536581e+10 | O5: 5.6536581e+10 | P5: =N5-O5 -> -0.00010681152
B6: LN - NP | C6: 0 | D6: 0 | E6: 11713762 | F6: 9728916 | G6: 20338326 | H6: 45751075 | I6: 16151025 | J6: 0 | K6: =SUM(C6:J6) -> 1.036831e+08 | M6: Gross | N6: =SUM(N4:N5) -> 5.9596524e+10 | O6: 5.5510701e+10 | P6: =N6-O6 -> 4.085823e+09
B7: P Total | C7: 0 | D7: 0 | E7: 2.7425593e+09 | F7: 4.7698933e+09 | G7: 1.2798813e+10 | H7: 2.4194861e+10 | I7: 6629196682 | J7: 112106166 | K7: =SUM(C7:J7) -> 5.124743e+10 | M7: (-) IIS | N7: =-R20 -> -3.452331e+08 | O7: -3.4962495e+08 | P7: =N7-O7 -> 4391854.3
B8: LE - P | C8: 0 | D8: 0 | E8: 2104518801 | F8: 3233366604 | G8: 6372561573 | H8: 17774434669 | I8: 3810728414 | J8: 14011640 | K8: =SUM(C8:J8) -> 33309621701 | M8: (-) IMP | N8: =-S20 -> -1.967969e+09 | O8: -1.9069219e+09 | P8: =N8-O8 -> -61047080
B9: LN - P | C9: 0 | D9: 0 | E9: 6.3804051e+08 | F9: 1.5365267e+09 | G9: 6.4262519e+09 | H9: 6.4204259e+09 | I9: 2818468268 | J9: 98094526 | K9: =SUM(C9:J9) -> 1.7937808e+10 | N9: =N6+N7+N8 -> 5.7283322e+10 | O9: =O6+O7+O8 -> 5.3254154e+10 | P9: =N9-O9 -> 4.0291678e+09
B10: Grand Total | C10: 0 | D10: 64590 | E10: 2.8617121e+09 | F10: 4.9393448e+09 | G10: 1.3113204e+10 | H10: 2.4872119e+10 | I10: 6716902915 | J10: 112106166 | K10: =SUM(C10:J10) -> 5.2615454e+10
A12: Base
B13: LE - P | C13: =C8/$K8 -> 0 | D13: =D8/$K8 -> 0 | E13: =E8/$K8 -> 0.063180507 | F13: =F8/$K8 -> 0.097070049 | G13: =G8/$K8 -> 0.19131294 | H13: =H8/$K8 -> 0.53361262 | I13: =I8/$K8 -> 0.11440323 | J13: =J8/$K8 -> 0.00042064843 | K13: =K8/$K8 -> 1 | N13: Arrears | O13: MOI | P13: Int Receivable | Q13: Deffered Promotion | R13: IIS | S13: Total IFRS Provision
B14: LE - NP | C14: =C5/$K5 -> 0 | D14: =D5/$K5 -> 5.108588e-05 | E14: =E5/$K5 -> 0.084976273 | F14: =F5/$K5 -> 0.12632863 | G14: =G5/$K5 -> 0.23257363 | H14: =H5/$K5 -> 0.49947555 | I14: =I5/$K5 -> 0.056594841 | J14: =J5/$K5 -> 0 | K14: =K5/$K5 -> 1 | M14: NP | N14: 7.3517414e+08 | O14: 3588381.3 | P14: 24824310 | Q14: 48804648 | R14: 3.1370538e+08 | S14: 1.0514693e+09
B15: LN - P | C15: =C9/$K9 -> 0 | D15: =D9/$K9 -> 0 | E15: =E9/$K9 -> 0.035569592 | F15: =F9/$K9 -> 0.085658556 | G15: =G9/$K9 -> 0.3582518 | H15: =H9/$K9 -> 0.35792701 | I15: =I9/$K9 -> 0.15712445 | J15: =J9/$K9 -> 0.0054685905 | K15: =K9/$K9 -> 1 | M15: Lease | N15: 6.2049931e+08 | O15: 3342252.8 | P15: 24399642 | Q15: 48804648 | R15: 2.8512361e+08 | S15: 9.4269867e+08
B16: LN - NP | C16: =C6/$K6 -> 0 | D16: =D6/$K6 -> 0 | E16: =E6/$K6 -> 0.11297657 | F16: =F6/$K6 -> 0.093833186 | G16: =G6/$K6 -> 0.19615854 | H16: =H6/$K6 -> 0.44125873 | I16: =I6/$K6 -> 0.15577297 | J16: =J6/$K6 -> 0 | K16: =K6/$K6 -> 1 | M16: Loan | N16: 1.1467483e+08 | O16: 246128.5 | P16: 424667.58 | Q16: 0 | R16: 28581766 | S16: 1.0877066e+08
M17: P | N17: 7.8165805e+08 | O17: 9352941.3 | P17: 5.8344918e+08 | Q17: 1.7342756e+09 | R17: 31527720 | S17: 9.1649969e+08
A18: Deffered Promotion | M18: Lease | N18: 7.8076087e+08 | O18: 8637808.9 | P18: 5.8095223e+08 | Q18: 1.7342756e+09 | R18: 31527720 | S18: 9.102276e+08
B19: LE - P | C19: =C13*$Q$18 -> 0 | D19: =D13*$Q$18 -> 0 | E19: =E13*$Q$18 -> 1.0957241e+08 | F19: =F13*$Q$18 -> 1.6834622e+08 | G19: =G13*$Q$18 -> 3.3178936e+08 | H19: =H13*$Q$18 -> 9.2543136e+08 | I19: =I13*$Q$18 -> 1.9840674e+08 | J19: =J13*$Q$18 -> 729520.31 | K19: =SUM(C19:J19) -> 1.7342756e+09 | M19: Loan | N19: 897179.99 | O19: 715132.41 | P19: 2496946 | Q19: 0 | R19: 0 | S19: 6272088.8
B20: LE - NP | C20: =C14*$Q$15 -> 0 | D20: =D14*$Q$15 -> 2493.2284 | E20: =E14*$Q$15 -> 4147237.1 | F20: =F14*$Q$15 -> 6165424.3 | G20: =G14*$Q$15 -> 11350674 | H20: =H14*$Q$15 -> 24376728 | I20: =I14*$Q$15 -> 2762091.3 | J20: =J14*$Q$15 -> 0 | K20: =SUM(C20:J20) -> 48804648 | N20: 1.5168322e+09 | O20: 12941323 | P20: 6.0827349e+08 | Q20: 1.7830803e+09 | R20: 3.452331e+08 | S20: 1.967969e+09
B21: LN - P | C21: =C15*$Q$19 -> 0 | D21: =D15*$Q$19 -> 0 | E21: =E15*$Q$19 -> 0 | F21: =F15*$Q$19 -> 0 | G21: =G15*$Q$19 -> 0 | H21: =H15*$Q$19 -> 0 | I21: =I15*$Q$19 -> 0 | J21: =J15*$Q$19 -> 0 | K21: =SUM(C21:J21) -> 0 | Q21: =K23-Q20 -> 0
B22: LN - NP | C22: 0 | D22: =D16*$Q$16 -> 0 | E22: =E16*$Q$16 -> 0 | F22: =F16*$Q$16 -> 0 | G22: =G16*$Q$16 -> 0 | H22: =H16*$Q$16 -> 0 | I22: =I16*$Q$16 -> 0 | J22: =J16*$Q$16 -> 0 | K22: =SUM(C22:J22) -> 0
C23: =SUM(C19:C22) -> 0 | D23: =SUM(D19:D22) -> 2493.2284 | E23: =SUM(E19:E22) -> 1.1371965e+08 | F23: =SUM(F19:F22) -> 1.7451164e+08 | G23: =SUM(G19:G22) -> 3.4314004e+08 | H23: =SUM(H19:H22) -> 9.4980809e+08 | I23: =SUM(I19:I22) -> 2.0116883e+08 | J23: =SUM(J19:J22) -> 729520.31 | K23: =SUM(K19:K22) -> 1.7830803e+09
N24: P | O24: NP | P24: Total
A25: Total Provision | M25: MT | N25: =O4 -> 3.0599423e+09 | P25: =N25+O25 -> 3.0599423e+09
B26: LE - P | C26: =C13*$S$18 -> 0 | D26: =D13*$S$18 -> 0 | E26: =E13*$S$18 -> 57508642 | F26: =F13*$S$18 -> 88355838 | G26: =G13*$S$18 -> 1.7413832e+08 | H26: =H13*$S$18 -> 4.8570894e+08 | I26: =I13*$S$18 -> 1.0413298e+08 | J26: =J13*$S$18 -> 382885.81 | K26: =SUM(C26:J26) -> 9.102276e+08 | M26: Future CAP | N26: =K7 -> 5.124743e+10 | O26: =K4 -> 1.3680246e+09 | P26: =N26+O26 -> 5.2615454e+10
B27: LE - NP | C27: =C14*$S$15 -> 0 | D27: =D14*$S$15 -> 48158.591 | E27: =E14*$S$15 -> 80107020 | F27: =F14*$S$15 -> 1.1908983e+08 | G27: =G14*$S$15 -> 2.1924685e+08 | H27: =H14*$S$15 -> 4.7085493e+08 | I27: =I14*$S$15 -> 53351881 | J27: =J14*$S$15 -> 0 | K27: =SUM(C27:J27) -> 9.4269867e+08 | M27: Arrears | O27: =N20 -> 1.5168322e+09 | P27: =N27+O27 -> 1.5168322e+09
B28: LN - P | C28: =C15*$S$19 -> 0 | D28: =(D15*$S$19) -> 0 | E28: =E15*$S$19 -> 223095.64 | F28: =F15*$S$19 -> 537258.07 | G28: =G15*$S$19 -> 2246987.1 | H28: =H15*$S$19 -> 2244950 | I28: =I15*$S$19 -> 985498.53 | J28: =J15*$S$19 -> 34299.485 | K28: =SUM(C28:J28) -> 6272088.8 | M28: MOI | O28: =O20 -> 12941323 | P28: =N28+O28 -> 12941323
B29: LN - NP | C29: =C16*$S$16 -> 0 | D29: =D16*$S$16 -> 0 | E29: =E16*$S$16 -> 12288537 | F29: =F16*$S$16 -> 10206298 | G29: =G16*$S$16 -> 21336295 | H29: =H16*$S$16 -> 47996005 | I29: =I16*$S$16 -> 16943529 | J29: =J16*$S$16 -> 0 | K29: =SUM(C29:J29) -> 1.0877066e+08 | M29: DP | N29: =Q17 -> 1.7342756e+09 | O29: =Q14 -> 48804648 | P29: =N29+O29 -> 1.7830803e+09
C30: =SUM(C26:C29) -> 0 | D30: =SUM(D26:D29) -> 48158.591 | E30: =SUM(E26:E29) -> 1.5012729e+08 | F30: =SUM(F26:F29) -> 2.1818922e+08 | G30: =SUM(G26:G29) -> 4.1696845e+08 | H30: =SUM(H26:H29) -> 1.0068048e+09 | I30: =SUM(I26:I29) -> 1.7541389e+08 | J30: =SUM(J26:J29) -> 417185.29 | K30: =SUM(K26:K29) -> 1.967969e+09 | M30: Gross | N30: =SUM(N25:N29) -> 5.6041647e+10 | O30: =SUM(O25:O29) -> 2.9466028e+09 | P30: =SUM(P25:P29) -> 5.898825e+10
M31: IIS | O31: =-R20 -> -3.452331e+08 | P31: =N31+O31 -> -3.452331e+08
A32: FD Loans | M32: IMP | N32: =-S17 -> -9.1649969e+08 | O32: =-S14 -> -1.0514693e+09 | P32: =N32+O32 -> -1.967969e+09
B33: Total P | C33: 4850916.6 | D33: 9261850 | E33: 4903428.7 | F33: 2194063.7 | G33: 5827324.9 | H33: 1536427.6 | I33: 201093.12 | J33: 0 | K33: =SUM(C33:J33) -> 28775105 | N33: =SUM(N30:N32) -> 5.5125148e+10 | O33: =SUM(O30:O32) -> 1.5499004e+09 | P33: =SUM(P30:P32) -> 5.6675048e+10
N34: =K36 -> 5.515365e+10 | O34: =K37 -> 2.1581739e+09 | P34: =N34+O34 -> 5.7311824e+10
M35: Front Back | N35: =N34-N33 -> 28502291 | O35: =O34-O33 -> 6.0827349e+08 | P35: =P34-P33 -> 6.3677578e+08
